Workbook

Sheet 00 Танилцуулга
A1: EJ Learning — системд хэрэгтэй өгөгдлийн бүтэц
A2: Хуудас бүр нь өгөгдлийн сангийн нэг хүснэгт. Аль хэдийн орсон өгөгдлийг цагаан дэвсгэртэй «БОДИТ» мөрөөр, ороогүй хэсгийг шар дэвсгэртэй «ЖИШЭЭ» мөрөөр үзүүлэв. Жишээ мөрүүд зохиомол боловч 6а ангийн бодит ном, бодит сэдэв, бодит багш нарын нэр дээр тулгуурласан — яг ямар өгөгдөл хэрэгтэйг харуулах зорилготой.
A4: Тэмдэглэгээ
A5: БОДИТ | B5: Баазад орсон жинхэнэ өгөгдөл. Өөрчлөх шаардлагагүй.
A6: ЖИШЭЭ | B6: Зохиомол мөр. Ямар өгөгдөл ямар хэлбэртэй байхыг харуулна.
A8: Хуудсуудын байдал
A9: Хуудас | B9: Агуулга | C9: Байдал | D9: Мөрийн тоо | E9: Танаас юу хэрэгтэй вэ
A10: 02 Хичээл | B10: Хичээлийн жагсаалт | C10: Бүрэн | D10: =COUNTA('02 Хичээл'!$A$6:$A$17) | E10: Байхгүй
A11: 03 Анги | B11: 14 анги | C11: Бараг бүрэн | D11: =COUNTA('03 Анги'!$A$6:$A$19) | E11: Анги бүрийн удирдсан багш (АУБ)
A12: 04 Багш | B12: 24 багш | C12: Бараг бүрэн | D12: =COUNTA('04 Багш'!$A$6:$A$29) | E12: Багш бүрийн үндсэн хичээл
A13: 05 Багш-анги-хичээл | B13: Хэн юу заадаг | C13: ХООСОН | D13: =COUNTA('05 Багш-анги-хичээл'!$A$6:$A$16) | E13: ★ Багш бүр аль ангид ямар хичээл заадаг
A14: 06 Сурагч | B14: 247 сурагч | C14: Бүрэн | D14: =COUNTA('06 Сурагч'!$A$6:$A$252) | E14: Байхгүй
A15: 07 Ном | B15: 6-р ангийн 11 ном | C15: Бүрэн | D15: =COUNTA('07 Ном'!$A$6:$A$16) | E15: Бусад ангиудын сурах бичиг
A16: 08 Анги-хичээл-ном | B16: Анги ямар хичээл үздэг | C16: Хэсэгчилсэн | D16: =COUNTA('08 Анги-хичээл-ном'!$A$6:$A$124) | E16: 13 ангийн жагсаалтыг батлах
A17: 09 Номын сэдэв | B17: Номын бүлэг, хуудас | C17: 2/11 ном | D17: =COUNTA('09 Номын сэдэв'!$A$6:$A$108) | E17: ★ Үлдсэн 9 номын сэдвийн задаргаа
A18: 10 Улирал | B18: 4 улирал | C18: Түр огноо | D18: =COUNTA('10 Улирал'!$A$6:$A$9) | E18: ★ Улирлын жинхэнэ огноо
A19: 11 Ангийн одоогийн сэдэв | B19: Анги хаана явж байна | C19: Эхэлсэн | D19: =COUNTA('11 Ангийн одоогийн сэдэв'!$A$6:$A$8) | E19: Багш нар өөрсдөө тэмдэглэнэ
A20: 12 Хичээлийн хуваарь | B20: Долоо хоногийн хуваарь | C20: ХООСОН | D20: =COUNTA('12 Хичээлийн хуваарь'!$A$6:$A$17) | E20: ★ Анги бүрийн хуваарь
A21: 13 Хичээлийн агуулга | B21: Хичээлийн бичвэр | C21: ХООСОН | D21: =COUNTA('13 Хичээлийн агуулга'!$A$6:$A$8) | E21: Хичээл бүрийн зорилт, тайлбар, дасгал
A22: 14 Чадвар | B22: Сурагч юу чаддаг болох ёстой | C22: ХООСОН | D22: =COUNTA('14 Чадвар'!$A$6:$A$11) | E22: ★ Хичээл бүрийн чадварын жагсаалт
A23: 15 Чадварын урьдач нөхцөл | B23: Чадвар ↔ чадвар гинж | C23: ХООСОН | D23: =COUNTA('15 Чадварын урьдач нөхцөл'!$A$6:$A$9) | E23: Аль чадварын өмнө юуг мэдэх ёстой
A24: 16 Сэдэв-чадвар-ном | B24: Чадвар ↔ номын сэдэв | C24: ХООСОН | D24: =COUNTA('16 Сэдэв-чадвар-ном'!$A$6:$A$11) | E24: ★ Чадварыг номын аль хэсгээр заадаг
A25: 17 Асуултын сан | B25: Асуулт → чадвар + сэдэв | C25: ХООСОН | D25: =COUNTA('17 Асуултын сан'!$A$6:$A$11) | E25: ★ Асуулт бүр, түүний чадвар ба номын сэдэв
A26: 18 Асуултын сонголт | B26: Сонголттой хариулт | C26: ХООСОН | D26: =COUNTA('18 Асуултын сонголт'!$A$6:$A$21) | E26: Хувилбар бүр ба аль нь зөв
A27: 19 Дасгал даалгавар | B27: Чадвар эзэмшүүлэх дасгал | C27: ХООСОН | D27: =COUNTA('19 Дасгал даалгавар'!$A$6:$A$9) | E27: Түвшин бүрийн дасгал
A28: 20 Эзэмшилт шалгах | B28: Эзэмшсэн эсэхийг шийдэх | C28: ХООСОН | D28: =COUNTA('20 Эзэмшилт шалгах'!$A$6:$A$8) | E28: Тэнцэх дүрэм ба дараагийн алхам
A29: 21 Шалгалт | B29: Шалгалтын хуудас | C29: ХООСОН | D29: =COUNTA('21 Шалгалт'!$A$6:$A$10) | E29: ★ Хэзээ, хэнд, ямар төрлийн шалгалт
A30: 22 Шалгалтын асуултууд | B30: Шалгалт ↔ асуулт | C30: ХООСОН | D30: =COUNTA('22 Шалгалтын асуултууд'!$A$6:$A$15) | E30: ★ Шалгалт бүр ямар асуултаас бүрдэх
A31: 23 Шалгалтын дүн | B31: Нийт оноо | C31: ХООСОН | D31: =COUNTA('23 Шалгалтын дүн'!$A$6:$A$10) | E31: Шалгалт болсны дараа
A32: 24 Асуултын хариулт | B32: Асуулт тус бүрийн хариулт | C32: ХООСОН | D32: =COUNTA('24 Асуултын хариулт'!$A$6:$A$12) | E32: ★ Үүнгүйгээр чадвар хэмжигдэхгүй
A33: 25 Чадварын түвшин | B33: Эцсийн үр дүн | C33: ХООСОН | D33: =COUNTA('25 Чадварын түвшин'!$A$6:$A$11) | E33: Автоматаар тооцогдоно
A34: 26 Хувийн ажил | B34: Хувийн бэлтгэл | C34: ХООСОН | D34: =COUNTA('26 Хувийн ажил'!$A$6:$A$9) | E34: Сурагч бүрд өгөх нэмэлт ажил
A36: Юунаас эхлэх вэ
A37: 1. «04 Багш-анги-хичээл» — багш бүр аль ангид ямар хичээл заадгийг бөглөх. Үүнгүйгээр багшийн дэлгэц ажиллахгүй.
A38: 2. «10 Улирал» — 4 улирлын жинхэнэ огноо.
A39: 3. «09 Номын сэдэв» — үлдсэн 9 номын бүлэг, сэдэв, хуудас.
A40: 4. «14 Чадвар» → «16 Сэдэв-чадвар-ном» — чадварын жагсаалт, дараа нь номын сэдэвтэй холбох.
A41: 5. «17 Асуултын сан» + «18 Асуултын сонголт» — асуулт бүрийг чадвар ба сэдэвтэй нь холбож оруулах.
A42: 6. «12 Хичээлийн хуваарь», дараа нь «21 Шалгалт».
A44: Эх сурвалж: ej_learning_local өгөгдлийн сан, 2026-09-22-ны байдлаар. Бодит мөрүүдийг баазаас шууд гаргасан; жишээ мөрүүдийг энэ файлд гар аргаар нэмсэн.

Sheet 01 Холбоосын бүдүүвч
A1: Юу юутай холбогдох вэ
A2: Асуулт нь ЧАДВАР болон НОМЫН СЭДЭВ ХОЁУЛАНД холбогдоно — тийм учраас нэг асуулт «энэ хүүхэд номын энэ хэсгийг ойлгов уу» болон «энэ чадварыг эзэмшив үү» гэсэн хоёр өөр асуултад хариулж чадна. Чадвар нь номд биш ХИЧЭЭЛД харьяалагдаж, номын сэдэвтэй агуулгын зангилаагаар дамжин холбогддог — ингэснээр ном солигдоход чадвар үлдэнэ.
A3: БОДИТ ӨГӨГДӨЛ — баазад бүрэн орсон
A5: Төлөв | B5: Юу | C5: → Юутай | D5: Баазын талбар / хүснэгт | E5: Заавал эсэх | F5: Тайлбар | G5: Хуудас
A6: БОДИТ | B6: Анги | C6: Хичээл + Ном | D6: class_subjects | E6: ЗААВАЛ | F6: Анги ямар хичээл үзэх, аль номоор. Ном нь хоосон байж болно. | G6: 08
A7: БОДИТ | B7: Анги | C7: Багш + Хичээл | D7: class_teachers | E7: ЗААВАЛ | F7: Хэн заадаг. Агуулгыг тодорхойлдоггүй — багш солигдоход агуулга үлдэнэ. | G7: 05
A8: БОДИТ | B8: Ном | C8: Номын сэдэв | D8: source_outline_nodes | E8: ЗААВАЛ | F8: Бүлэг, сэдэв, хуудас, аль улиралд үзэх. | G8: 09
A9: БОДИТ | B9: Анги | C9: Одоогийн сэдэв | D9: class_topics | E9: СОНГОХ | F9: Багш «одоо энд явж байна» гэж заана. Хуанлиас тооцогддоггүй. | G9: 11
A10: БОДИТ | B10: Чадвар | C10: Хичээл + Анги | D10: skills.subject_id, grade_level_id | E10: ЗААВАЛ | F10: Чадвар ХИЧЭЭЛД харьяалагдана, номд биш. Ном солигдоход чадвар үлдэнэ. | G10: 14
A11: БОДИТ | B11: Чадвар | C11: Англи хэлний түвшин | D11: skills.proficiency_level_id | E11: СОНГОХ | F11: Англи хэл дээр чадвар ангид биш CEFR түвшинд (A1–C2) наалддаг. | G11: 14
A12: БОДИТ | B12: Чадвар | C12: Урьдач чадвар | D12: skill_dependencies | E12: СОНГОХ | F12: Аль чадварыг эзэмшихийн өмнө юуг мэдэх ёстой. Нөхөх ажлыг энэ гинжээр олно. | G12: 15
A13: БОДИТ | B13: Чадвар | C13: Номын сэдэв | D13: content_nodes → content_skill_maps + content_source_alignments | E13: ЗААВАЛ | F13: Чадварыг номын аль хэсгээр заадаг. Шууд биш, агуулгын зангилаагаар дамжина. | G13: 16
A14: БОДИТ | B14: АСУУЛТ | C14: Чадвар | D14: diagnostic_items.skill_id | E14: СОНГОХ (гэхдээ шаардлагатай) | F14: Аль чадварыг хэмжиж байгаа. Байхгүй бол ахиц хэмжигдэхгүй. | G14: 17
A15: БОДИТ | B15: АСУУЛТ | C15: Номын сэдэв | D15: diagnostic_items.source_outline_node_id | E15: СОНГОХ | F15: Номын аль хэсгийн дараа асуух. Байхгүй бол чадварын БҮХ өдөр харагдана. | G15: 17
A16: БОДИТ | B16: Асуулт | C16: Хичээл + Анги | D16: diagnostic_items.subject_id, grade_level_id | E16: ЗААВАЛ | F16: Аль хичээл, ямар ангид зориулсан. | G16: 17
... A26: БОДИТ | B26: Хувийн ажил | C26: Сурагч + Хичээл | D26: student_assignments | E26: СОНГОХ | F26: Чадварын түвшнээс хамаарч оногдоно. Үндсэн номыг орлохгүй. | G26: 25
A28: 6а Математикийн жишээг 14-24-р хуудсаар дагаж болно: чадвар MATH-6-03 → номын сэдэв II.4 (30-31 х.) → асуулт Q-M6-0301 → Батбаяр Мишээлийн хариулт → түүний чадварын түвшин.

Sheet 02 Хичээл
A1: Хичээлийн жагсаалт
A2: Системд бүртгэлтэй хичээлүүд. Хичээл бүр код (MATH, MGL гэх мэт) болон монгол нэртэй. Бусад бүх хуудас хичээл рүү энэ кодоор заана.
A3: БОДИТ ӨГӨГДӨЛ — баазад бүрэн орсон
A5: Төлөв | B5: Хичээлийн код | C5: Хичээлийн нэр | D5: Хэдэн ангид заагдаж байгаа | E5: Тэдгээрээс номтой нь | F5: Тэмдэглэл
A6: БОДИТ | B6: ART | C6: Дүрслэх урлаг | D6: =COUNTIF('08 Анги-хичээл-ном'!$C$6:$C$124,$B6) | E6: =COUNTIFS('08 Анги-хичээл-ном'!$C$6:$C$124,$B6,'08 Анги-хичээл-ном'!$F$6:$F$124,"<>")
A7: БОДИТ | B7: DTECH | C7: Дизайн технологи | D7: =COUNTIF('08 Анги-хичээл-ном'!$C$6:$C$124,$B7) | E7: =COUNTIFS('08 Анги-хичээл-ном'!$C$6:$C$124,$B7,'08 Анги-хичээл-ном'!$F$6:$F$124,"<>")
A8: БОДИТ | B8: ENG | C8: Англи хэл | D8: =COUNTIF('08 Анги-хичээл-ном'!$C$6:$C$124,$B8) | E8: =COUNTIFS('08 Анги-хичээл-ном'!$C$6:$C$124,$B8,'08 Анги-хичээл-ном'!$F$6:$F$124,"<>")
A9: БОДИТ | B9: ETHICS | C9: Иргэний ёс зүйн боловсрол | D9: =COUNTIF('08 Анги-хичээл-ном'!$C$6:$C$124,$B9) | E9: =COUNTIFS('08 Анги-хичээл-ном'!$C$6:$C$124,$B9,'08 Анги-хичээл-ном'!$F$6:$F$124,"<>")
A10: БОДИТ | B10: HIST | C10: Түүх | D10: =COUNTIF('08 Анги-хичээл-ном'!$C$6:$C$124,$B10) | E10: =COUNTIFS('08 Анги-хичээл-ном'!$C$6:$C$124,$B10,'08 Анги-хичээл-ном'!$F$6:$F$124,"<>")
A11: БОДИТ | B11: ICT | C11: Мэдээллийн технологи | D11: =COUNTIF('08 Анги-хичээл-ном'!$C$6:$C$124,$B11) | E11: =COUNTIFS('08 Анги-хичээл-ном'!$C$6:$C$124,$B11,'08 Анги-хичээл-ном'!$F$6:$F$124,"<>")
A12: БОДИТ | B12: LIT | C12: Уран зохиол | D12: =COUNTIF('08 Анги-хичээл-ном'!$C$6:$C$124,$B12) | E12: =COUNTIFS('08 Анги-хичээл-ном'!$C$6:$C$124,$B12,'08 Анги-хичээл-ном'!$F$6:$F$124,"<>")
A13: БОДИТ | B13: MATH | C13: Математик | D13: =COUNTIF('08 Анги-хичээл-ном'!$C$6:$C$124,$B13) | E13: =COUNTIFS('08 Анги-хичээл-ном'!$C$6:$C$124,$B13,'08 Анги-хичээл-ном'!$F$6:$F$124,"<>")
A14: БОДИТ | B14: MGL | C14: Монгол хэл | D14: =COUNTIF('08 Анги-хичээл-ном'!$C$6:$C$124,$B14) | E14: =COUNTIFS('08 Анги-хичээл-ном'!$C$6:$C$124,$B14,'08 Анги-хичээл-ном'!$F$6:$F$124,"<>")
A15: ЖИШЭЭ | B15: PHYS | C15: Физик — local demo | D15: =COUNTIF('08 Анги-хичээл-ном'!$C$6:$C$124,$B15) | E15: =COUNTIFS('08 Анги-хичээл-ном'!$C$6:$C$124,$B15,'08 Анги-хичээл-ном'!$F$6:$F$124,"<>") | F15: Хөгжүүлэлтийн туршилтын мөр — устгана
A16: БОДИТ | B16: SCI | C16: Байгалийн ухаан | D16: =COUNTIF('08 Анги-хичээл-ном'!$C$6:$C$124,$B16) | E16: =COUNTIFS('08 Анги-хичээл-ном'!$C$6:$C$124,$B16,'08 Анги-хичээл-ном'!$F$6:$F$124,"<>")
A17: БОДИТ | B17: SCRIPT | C17: Үндэсний бичиг | D17: =COUNTIF('08 Анги-хичээл-ном'!$C$6:$C$124,$B17) | E17: =COUNTIFS('08 Анги-хичээл-ном'!$C$6:$C$124,$B17,'08 Анги-хичээл-ном'!$F$6:$F$124,"<>")
A19: «Физик — local demo» нь хөгжүүлэлтийн туршилтын мөр, бодит хичээл биш.

Sheet 03 Анги
A1: Ангиуд
A2: 2026-2027 оны хичээлийн жилийн бүх анги. Сурагчийн тоо «05 Сурагч» хуудаснаас автоматаар тоологдоно. Ангийн удирдсан багш (АУБ) баазад хоосон — шар нүд нь жишээ.
A3: ЗАРИМ НЬ ОРСОН — дутууг нөхөх шаардлагатай
A5: Төлөв | B5: Ангийн код | C5: Ангийн нэр | D5: Анги | E5: Хичээлийн жил | F5: Сурагчийн тоо | G5: Ангийн удирдсан багш (АУБ) | H5: Тэмдэглэл
A6: БОДИТ | B6: EJ-2627-1A | C6: 1а | D6: 1 | E6: 2026-2027 | F6: =COUNTIF('06 Сурагч'!$D$6:$D$252,$B6) | G6: Д.Дэлгэрмаа (EJ-2627-T009) | H6: АУБ-г жишээгээр харуулав
A7: БОДИТ | B7: EJ-2627-2A | C7: 2а | D7: 2 | E7: 2026-2027 | F7: =COUNTIF('06 Сурагч'!$D$6:$D$252,$B7) | H7: АУБ бөглөөгүй
A8: БОДИТ | B8: EJ-2627-3A | C8: 3а | D8: 3 | E8: 2026-2027 | F8: =COUNTIF('06 Сурагч'!$D$6:$D$252,$B8) | H8: АУБ бөглөөгүй
A9: БОДИТ | B9: EJ-2627-4A | C9: 4а | D9: 4 | E9: 2026-2027 | F9: =COUNTIF('06 Сурагч'!$D$6:$D$252,$B9) | H9: АУБ бөглөөгүй
A10: БОДИТ | B10: EJ-2627-5A | C10: 5а | D10: 5 | E10: 2026-2027 | F10: =COUNTIF('06 Сурагч'!$D$6:$D$252,$B10) | H10: АУБ бөглөөгүй
A11: БОДИТ | B11: EJ-2627-6A | C11: 6а | D11: 6 | E11: 2026-2027 | F11: =COUNTIF('06 Сурагч'!$D$6:$D$252,$B11) | G11: Б.Буянзаяа (EJ-2627-T005) | H11: АУБ-г жишээгээр харуулав
A12: БОДИТ | B12: EJ-2627-7A | C12: 7а | D12: 7 | E12: 2026-2027 | F12: =COUNTIF('06 Сурагч'!$D$6:$D$252,$B12) | H12: АУБ бөглөөгүй
A13: БОДИТ | B13: EJ-2627-7B | C13: 7б | D13: 7 | E13: 2026-2027 | F13: =COUNTIF('06 Сурагч'!$D$6:$D$252,$B13) | H13: АУБ бөглөөгүй
A14: БОДИТ | B14: EJ-2627-8A | C14: 8а | D14: 8 | E14: 2026-2027 | F14: =COUNTIF('06 Сурагч'!$D$6:$D$252,$B14) | H14: АУБ бөглөөгүй
A15: БОДИТ | B15: EJ-2627-9A | C15: 9а | D15: 9 | E15: 2026-2027 | F15: =COUNTIF('06 Сурагч'!$D$6:$D$252,$B15) | H15: АУБ бөглөөгүй
A16: БОДИТ | B16: EJ-2627-9B | C16: 9б | D16: 9 | E16: 2026-2027 | F16: =COUNTIF('06 Сурагч'!$D$6:$D$252,$B16) | H16: АУБ бөглөөгүй
A17: БОДИТ | B17: EJ-2627-10A | C17: 10а | D17: 10 | E17: 2026-2027 | F17: =COUNTIF('06 Сурагч'!$D$6:$D$252,$B17) | H17: АУБ бөглөөгүй
A18: БОДИТ | B18: EJ-2627-11A | C18: 11а | D18: 11 | E18: 2026-2027 | F18: =COUNTIF('06 Сурагч'!$D$6:$D$252,$B18) | H18: АУБ бөглөөгүй
A19: БОДИТ | B19: EJ-2627-12A | C19: 12а | D19: 12 | E19: 2026-2027 | F19: =COUNTIF('06 Сурагч'!$D$6:$D$252,$B19) | H19: АУБ бөглөөгүй
A21: АУБ нь «хэн ямар хичээл заадаг»-аас өөр ойлголт. АУБ ангийн бүх хичээлийг хардаг ч зөвхөн өөрийн заадаг хичээлээ засна.

Sheet 04 Багш
A1: Багш нар
A2: Сургуулийн 24 багш. Нэр, нэвтрэх бүртгэл орсон. «Мэргэжил» баганыг ажилтны бүртгэлийн албан тушаалаас гаргав — энэ нь одоогоор баазад хадгалагддаггүй. «Үндсэн хичээл» бүгд хоосон.
A3: ЗАРИМ НЬ ОРСОН — дутууг нөхөх шаардлагатай
A5: Төлөв | B5: Багшийн код | C5: Овог нэр | D5: Нэвтрэх нэр | E5: Мэргэжил (бүртгэлээс) | F5: Үндсэн хичээлийн код | G5: Хариуцсан анги-хичээл | H5: Тэмдэглэл
A6: БОДИТ | B6: EJ-2627-T001 | C6: Б.Амартүвшин | D6: ej26t001 | E6: Түүх, нийгэм судлал | G6: =COUNTIF('05 Багш-анги-хичээл'!$B$6:$B$40,$B6) | H6: Үндсэн хичээл баазад хоосон
A7: БОДИТ | B7: EJ-2627-T003 | C7: Г.Батцэцэг | D7: ej26t002 | E7: Биеийн тамир | G7: =COUNTIF('05 Багш-анги-хичээл'!$B$6:$B$40,$B7) | H7: Үндсэн хичээл баазад хоосон
A8: БОДИТ | B8: EJ-2627-T004 | C8: Х.Болор-Эрдэнэ | D8: ej26t003 | E8: Физик | G8: =COUNTIF('05 Багш-анги-хичээл'!$B$6:$B$40,$B8) | H8: Үндсэн хичээл баазад хоосон
A9: БОДИТ | B9: EJ-2627-T005 | C9: Б.Буянзаяа | D9: ej26t004 | E9: Математик | G9: =COUNTIF('05 Багш-анги-хичээл'!$B$6:$B$40,$B9) | H9: Үндсэн хичээл баазад хоосон
A10: БОДИТ | B10: EJ-2627-T006 | C10: Д.Ганбат | D10: ej26t005 | E10: Физик | G10: =COUNTIF('05 Багш-анги-хичээл'!$B$6:$B$40,$B10) | H10: Үндсэн хичээл баазад хоосон
A11: БОДИТ | B11: EJ-2627-T007 | C11: Б.Гансүх | D11: ej26t006 | E11: Математик | G11: =COUNTIF('05 Багш-анги-хичээл'!$B$6:$B$40,$B11) | H11: Үндсэн хичээл баазад хоосон
A12: БОДИТ | B12: EJ-2627-T008 | C12: Э.Дуламсүрэн | D12: ej26t007 | E12: Англи хэл | G12: =COUNTIF('05 Багш-анги-хичээл'!$B$6:$B$40,$B12) | H12: Үндсэн хичээл баазад хоосон
A13: БОДИТ | B13: EJ-2627-T009 | C13: Д.Дэлгэрмаа | D13: ej26t008 | E13: Бага анги | G13: =COUNTIF('05 Багш-анги-хичээл'!$B$6:$B$40,$B13) | H13: Үндсэн хичээл баазад хоосон
A14: БОДИТ | B14: EJ-2627-T010 | C14: А.Мөнхнаран | D14: ej26t009 | E14: Нийгэм, газарзүй | G14: =COUNTIF('05 Багш-анги-хичээл'!$B$6:$B$40,$B14) | H14: Үндсэн хичээл баазад хоосон
A15: БОДИТ | B15: EJ-2627-T013 | C15: Б.Нандинцэцэг | D15: ej26t010 | E15: Математик | G15: =COUNTIF('05 Багш-анги-хичээл'!$B$6:$B$40,$B15) | H15: Үндсэн хичээл баазад хоосон
A16: БОДИТ | B16: EJ-2627-T014 | C16: Н.Нансал | D16: ej26t011 | E16: Монгол хэл, уран зохиол | G16: =COUNTIF('05 Багш-анги-хичээл'!$B$6:$B$40,$B16) | H16: Үндсэн хичээл баазад хоосон
A17: БОДИТ | B17: EJ-2627-T015 | C17: Э.Номуундарь | D17: ej26t012 | E17: Зураг, технологи | G17: =COUNTIF('05 Багш-анги-хичээл'!$B$6:$B$40,$B17) | H17: Үндсэн хичээл баазад хоосон
... A29: БОДИТ | B29: EJ-2627-T030 | C29: Т.Эрдэнээ | D29: ej26t024 | E29: Монгол хэл, уран зохиол | G29: =COUNTIF('05 Багш-анги-хичээл'!$B$6:$B$40,$B29) | H29: Үндсэн хичээл баазад хоосон
A31: Бүртгэлд мэдээллийн технологи, үндэсний бичгийн багш алга. 6-р ангид эдгээр хичээл номтой байгаа тул хэн заахыг тодруулах шаардлагатай.

Sheet 05 Багш-анги-хичээл
A1: Багш ↔ анги ↔ хичээл (★ ХАМГИЙН ЧУХАЛ)
A2: «Хэн, аль ангид, ямар хичээл заадаг вэ». Энэ хүснэгт БҮХЭЛДЭЭ ХООСОН. Багшийн дэлгэц, үнэлгээ, шалгалтын эрх бүгд үүнээс хамаарна. Доорх нь 6а ангийн жишээ — багш нарыг мэргэжлээр нь тааруулж харуулав, сургууль баталгаажуулах ёстой.
A3: ХООСОН — бүхэлдээ сургуулиас авах ёстой
A5: Төлөв | B5: Багшийн код | C5: Багшийн нэр | D5: Ангийн код | E5: Анги | F5: Хичээлийн код | G5: Хичээл | H5: Үүрэг | I5: Тэмдэглэл
A6: ЖИШЭЭ | B6: EJ-2627-T005 | C6: Б.Буянзаяа | D6: EJ-2627-6A | E6: 6а | F6: MATH | G6: Математик | H6: Заадаг + АУБ
A7: ЖИШЭЭ | B7: EJ-2627-T014 | C7: Н.Нансал | D7: EJ-2627-6A | E7: 6а | F7: MGL | G7: Монгол хэл | H7: Заадаг
A8: ЖИШЭЭ | B8: EJ-2627-T030 | C8: Т.Эрдэнээ | D8: EJ-2627-6A | E8: 6а | F8: LIT | G8: Уран зохиол | H8: Заадаг
A9: ЖИШЭЭ | B9: EJ-2627-T001 | C9: Б.Амартүвшин | D9: EJ-2627-6A | E9: 6а | F9: HIST | G9: Түүх | H9: Заадаг
A10: ЖИШЭЭ | B10: EJ-2627-T008 | C10: Э.Дуламсүрэн | D10: EJ-2627-6A | E10: 6а | F10: ENG | G10: Англи хэл | H10: Заадаг
A11: ЖИШЭЭ | B11: EJ-2627-T018 | C11: Б.Отгонбулаг | D11: EJ-2627-6A | E11: 6а | F11: SCI | G11: Байгалийн ухаан | H11: Заадаг
A12: ЖИШЭЭ | B12: EJ-2627-T015 | C12: Э.Номуундарь | D12: EJ-2627-6A | E12: 6а | F12: ART | G12: Дүрслэх урлаг | H12: Заадаг
A13: ЖИШЭЭ | B13: EJ-2627-T015 | C13: Э.Номуундарь | D13: EJ-2627-6A | E13: 6а | F13: DTECH | G13: Дизайн технологи | H13: Заадаг | I13: Нэг багш нэг ангид хоёр хичээл заах нь боломжтой
A14: ЖИШЭЭ | B14: EJ-2627-T010 | C14: А.Мөнхнаран | D14: EJ-2627-6A | E14: 6а | F14: ETHICS | G14: Иргэний ёс зүйн боловсрол | H14: Заадаг
A15: ЖИШЭЭ | D15: EJ-2627-6A | E15: 6а | F15: ICT | G15: Мэдээллийн технологи | H15: Заадаг | I15: Бүртгэлд энэ хичээлийн багш олдсонгүй — хэн заахыг бөглөнө үү
A16: ЖИШЭЭ | D16: EJ-2627-6A | E16: 6а | F16: SCRIPT | G16: Үндэсний бичиг | H16: Заадаг | I16: Бүртгэлд энэ хичээлийн багш олдсонгүй — хэн заахыг бөглөнө үү
A42: Хэрэгтэй зүйл: анги бүрийн заагдах хичээл бүрд нэг мөр — нийт 119 орчим мөр («07 Анги-хичээл-ном» хуудсыг үзнэ үү). Доорх хоосон мөрүүдэд шинэ мөр нэмж болно: «03 Багш» хуудасны тоолол 40-р мөр хүртэл автоматаар шинэчлэгдэнэ.

Sheet 06 Сурагч
A1: Сурагчид
A2: 247 сурагч анги бүртэйгээ холбогдож, нэвтрэх бүртгэл үүссэн. Энэ хэсэг бүрэн бэлэн.
A3: БОДИТ ӨГӨГДӨЛ — баазад бүрэн орсон
A5: Төлөв | B5: Сурагчийн код | C5: Овог нэр | D5: Ангийн код | E5: Анги | F5: Анги (тоо) | G5: Нэвтрэх нэр | H5: Гадаад код | I5: Идэвхтэй
A6: БОДИТ | B6: EJ-2627-S0006 | C6: Алтаншагай Маргад | D6: EJ-2627-1A | E6: 1а | F6: 1 | G6: ej26s0006 | H6: УЦ20320921 | I6: Тийм
A7: БОДИТ | B7: EJ-2627-S0007 | C7: Амарболд Ялгуунгоо | D7: EJ-2627-1A | E7: 1а | F7: 1 | G7: ej26s0007 | H7: ТА20320523 | I7: Тийм
A8: БОДИТ | B8: EJ-2627-S0012 | C8: Анхбаяр Өнөмандах | D8: EJ-2627-1A | E8: 1а | F8: 1 | G8: ej26s0012 | H8: УШ20250734 | I8: Тийм
A9: БОДИТ | B9: EJ-2627-S0002 | C9: Анхсүрэн Мөнхсүрэн | D9: EJ-2627-1A | E9: 1а | F9: 1 | G9: ej26s0002 | H9: УШ20261570 | I9: Тийм
A10: БОДИТ | B10: EJ-2627-S0014 | C10: Батбаяр Төгөлдөрбуян | D10: EJ-2627-1A | E10: 1а | F10: 1 | G10: ej26s0014 | H10: УВ20291691 | I10: Тийм
A11: БОДИТ | B11: EJ-2627-S0013 | C11: Батзориг Амингоо | D11: EJ-2627-1A | E11: 1а | F11: 1 | G11: ej26s0013 | H11: УК20232369 | I11: Тийм
A12: БОДИТ | B12: EJ-2627-S0003 | C12: Батнасан Гуамарал | D12: EJ-2627-1A | E12: 1а | F12: 1 | G12: ej26s0003 | H12: ун20291861 | I12: Тийм
A13: БОДИТ | B13: EJ-2627-S0001 | C13: Баттулга Энхлэн | D13: EJ-2627-1A | E13: 1а | F13: 1 | G13: ej26s0001 | H13: ФЭ20232461 | I13: Тийм
A14: БОДИТ | B14: EJ-2627-S0005 | C14: Баттүшиг Бэлгүдэй | D14: EJ-2627-1A | E14: 1а | F14: 1 | G14: ej26s0005 | H14: ЩК20302312 | I14: Тийм
A15: БОДИТ | B15: EJ-2627-S0004 | C15: Идэрцогт Бишрэлтбаяр | D15: EJ-2627-1A | E15: 1а | F15: 1 | G15: ej26s0004 | H15: УП20301334 | I15: Тийм
A16: БОДИТ | B16: EJ-2627-S0011 | C16: Ихбаяр Энх-Үжин | D16: EJ-2627-1A | E16: 1а | F16: 1 | G16: ej26s0011 | H16: УВ20281047 | I16: Тийм
A17: БОДИТ | B17: EJ-2627-S0009 | C17: Ичинхорол Аззаяа | D17: EJ-2627-1A | E17: 1а | F17: 1 | G17: ej26s0009 | H17: УШ20300403 | I17: Тийм
... A51: БОДИТ | B51: EJ-2627-S0042 | C51: Содбаяр Нэгүүн | D51: EJ-2627-3A | E51: 3а | F51: 3 | G51: ej26s0042 | H51: УЗ18231333 | I51: Тийм
A52: БОДИТ | B52: EJ-2627-S0050 | C52: Содбилэг | D52: EJ-2627-3A | E52: 3а | F52: 3 | G52: ej26s0050 | I52: Тийм
A53: БОДИТ | B53: EJ-2627-S0037 | C53: Уранчимэг Ананд | D53: EJ-2627-3A | E53: 3а | F53: 3 | G53: ej26s0037 | H53: ЩШ18210336 | I53: Тийм
A54: БОДИТ | B54: EJ-2627-S0049 | C54: Энхмэнд Урам | D54: EJ-2627-3A | E54: 3а | F54: 3 | G54: ej26s0049 | H54: УО18221367 | I54: Тийм
A55: БОДИТ | B55: EJ-2627-S0045 | C55: Эрдэнэбаяр Цэцэгхэн | D55: EJ-2627-3A | E55: 3а | F55: 3 | G55: ej26s0045 | H55: УЗ18302125 | I55: Тийм
A56: БОДИТ | B56: EJ-2627-S0078 | C56: Анир Бодь | D56: EJ-2627-4A | E56: 4а | F56: 4 | G56: ej26s0078 | H56: МЗ17211919 | I56: Тийм
A57: БОДИТ | B57: EJ-2627-S0074 | C57: Бат-Очир Энхрийлэн | D57: EJ-2627-4A | E57: 4а | F57: 4 | G57: ej26s0074 | H57: уб17322180 | I57: Тийм
A58: БОДИТ | B58: EJ-2627-S0052 | C58: Батбаатар Баттүшиг | D58: EJ-2627-4A | E58: 4а | F58: 4 | G58: ej26s0052 | H58: УЖ17282955 | I58: Тийм
A59: БОДИТ | B59: EJ-2627-S0070 | C59: Батгэрэл Эрдэмтүшиг | D59: EJ-2627-4A | E59: 4а | F59: 4 | G59: ej26s0070 | H59: УЗ17291331 | I59: Тийм
A60: БОДИТ | B60: EJ-2627-S0073 | C60: Батнасан Хосбаяр | D60: EJ-2627-4A | E60: 4а | F60: 4 | G60: ej26s0073 | H60: ГЮ17280415 | I60: Тийм
A61: БОДИТ | B61: EJ-2627-S0065 | C61: Булгантамир Сэцэнгоо | D61: EJ-2627-4A | E61: 4а | F61: 4 | G61: ej26s0065 | H61: УВ17232088 | I61: Тийм
A62: БОДИТ | B62: EJ-2627-S0062 | C62: Ганбаяр Мэнд-Амар | D62: EJ-2627-4A | E62: 4а | F62: 4 | G62: ej26s0062 | H62: УЗ17250251 | I62: Тийм
A63: БОДИТ | B63: EJ-2627-S0072 | C63: Гантулга Цэцбилэг | D63: EJ-2627-4A | E63: 4а | F63: 4 | G63: ej26s0072 | H63: УЖ17231237 | I63: Тийм
A64: БОДИТ | B64: EJ-2627-S0067 | C64: Ганцог Тэмүүлэн | D64: EJ-2627-4A | E64: 4а | F64: 4 | G64: ej26s0067 | H64: УБ17282074 | I64: Тийм
... A252: БОДИТ | B252: EJ-2627-S0242 | C252: Эрдэнэхүү Ган-Эрдэнэ | D252: EJ-2627-12A | E252: 12а | F252: 12 | G252: ej26s0240 | H252: УТ08323136 | I252: Тийм

Sheet 07 Ном
A1: Сурах бичиг
A2: 6-р ангийн 11 ном PDF-ээрээ системд орсон. «Сэдвийн тоо» нь «08 Номын сэдэв» хуудаснаас тоологдоно — зөвхөн Математик, Монгол хэл хоёрын задаргаа орсон байна.
A3: ЗАРИМ НЬ ОРСОН — дутууг нөхөх шаардлагатай
A5: Төлөв | B5: Номын код | C5: Хичээл | D5: Номын нэр | E5: Зохиогч | F5: Хэвлэсэн он | G5: Хэвлэл | H5: Нийт хуудас | I5: Анги | J5: Улирлын тоо | K5: Сэдвийн тоо
A6: БОДИТ | B6: G06-ART-MN | C6: Дүрслэх урлаг | D6: Дүрслэх урлаг VI–VII | E6: О.Нацагдорж, С.Батчулуун, Б.Баттулга, Г.Мэндээ, Ж.Өнөржаргал, Н.Хүдэрчулуун | F6: 2023 | G6: Тав дахь хэвлэл | H6: 116 | I6: 6 | K6: =COUNTIF('09 Номын сэдэв'!$B$6:$B$108,$B6)
A7: БОДИТ | B7: G06-DTECH-MN | C7: Дизайн технологи | D7: Дизайн технологи VI | E7: А.Алтантуул, Ч.Алтанчимэг, М.Баасанбаяр, В.Баяржаргал, Р.Гоцбаяр, С.Нямсүрэн, Д.Сэрээтэрдорж, Г.Чулуун | F7: 2023 | G7: Тав дахь хэвлэл | H7: 108 | I7: 6 | K7: =COUNTIF('09 Номын сэдэв'!$B$6:$B$108,$B7)
A8: БОДИТ | B8: G06-ETHICS-MN | C8: Иргэний ёс зүйн боловсрол | D8: Иргэний ёс зүйн боловсрол VI | E8: Б.Цасанчимэг, Ө.Цэндсүрэн, Ж.Гэрэлмаа | F8: 2023 | G8: Хоёр дахь хэвлэл | H8: 88 | I8: 6 | K8: =COUNTIF('09 Номын сэдэв'!$B$6:$B$108,$B8)
A9: БОДИТ | B9: G06-HIST-MN | C9: Түүх | D9: Түүх VI | E9: П.Дэлгэржаргал, У.Туяа, Б.Чинзориг, Д.Янжинжав | F9: 2023 | G9: Долоо дахь хэвлэл | H9: 84 | I9: 6 | K9: =COUNTIF('09 Номын сэдэв'!$B$6:$B$108,$B9)
A10: БОДИТ | B10: G06-ICT-MN | C10: Мэдээллийн технологи | D10: Мэдээллийн технологи VI | E10: Д.Цэдэвсүрэн, С.Уянга, Л.Мөнхтуяа, Э.Оюунбилэг, Ш.Отгонцэцэг, П.Дэлгэржав | F10: 2023 | G10: Долоо дахь хэвлэл | H10: 56 | I10: 6 | K10: =COUNTIF('09 Номын сэдэв'!$B$6:$B$108,$B10)
A11: БОДИТ | B11: G06-LIT-MN | C11: Уран зохиол | D11: Уран зохиол VI | E11: П.Одсүрэн, С.Амарсайхан, Ч.Жачин, Т.Мөнхнаран, Г.Нандинбилиг, Д.Цогзолмаа | F11: 2023 | G11: Долоо дахь хэвлэл | H11: 96 | I11: 6 | K11: =COUNTIF('09 Номын сэдэв'!$B$6:$B$108,$B11)
A12: БОДИТ | B12: G06-MATH-MN | C12: Математик | D12: Математик VI | E12: Д.Түвшинжаргал, Ж.Батболд, Д.Даваасүрэн, Э.Чойсүрэн, Т.Батчимэг, Н.Баянбилэг, Н.Гэндэнсүрэн, Б.Равданжамц, Н.Цогзолмаа, Б.Энхболд, Д.Энхцэцэг, Б.Эрдэн | F12: 2022 | G12: Долоо дахь хэвлэл | H12: 168 | I12: 6 | J12: 3 | K12: =COUNTIF('09 Номын сэдэв'!$B$6:$B$108,$B12)
A13: БОДИТ | B13: G06-MGL-MN | C13: Монгол хэл | D13: Монгол хэл VI | E13: Ш.Оюунцэцэг, Б.Мөнгөнцэцэг, Л.Олзвой, Ц.Оюун, Ц.Туул | F13: 2023 | G13: Долоо дахь хэвлэл | H13: 152 | I13: 6 | J13: 3 | K13: =COUNTIF('09 Номын сэдэв'!$B$6:$B$108,$B13)
A14: БОДИТ | B14: G06-SCI-OXFORD | C14: Байгалийн ухаан | D14: Oxford International Primary Science 6 | H14: 153 | I14: 6 | K14: =COUNTIF('09 Номын сэдэв'!$B$6:$B$108,$B14)
A15: БОДИТ | B15: G06-SCI-MN | C15: Байгалийн ухаан | D15: Байгалийн ухаан VI | E15: С.Гэндэнжамц, Д.Батболд, Ц.Амартайван, Ж.Дөлгөөн, Б.Бадам, А.Энхтогтох, С.Цогбадрах, Х.Тэрбиш, М.Мөнхбаатар, Г.Баярмаа, Д.Сарангэрэл, Н.Оюунцэцэг, Н.Н | F15: 2023 | G15: Долоо дахь хэвлэл | H15: 136 | I15: 6 | K15: =COUNTIF('09 Номын сэдэв'!$B$6:$B$108,$B15)
A16: БОДИТ | B16: G06-SCRIPT-MN | C16: Үндэсний бичиг | D16: Үндэсний бичиг VI | E16: Ш.Чоймаа, Д.Хишигсүрэн, Д.Эрдэнэсанаа, Л.Жумдаан, Р.Өлзийхүү, Н.Золжаргал, Э.Эрдэнэзуу | F16: 2023 | G16: Долоо дахь хэвлэл | H16: 96 | I16: 6 | K16: =COUNTIF('09 Номын сэдэв'!$B$6:$B$108,$B16)
A18: Улирлын тоо = 3. Сургууль 4 улиралтай ч агуулгыг эхний 3-т багтаадаг; 4 дэх нь давтлага, шалгалт.

Sheet 08 Анги-хичээл-ном
A1: Анги ↔ хичээл ↔ үндсэн ном
A2: Анги бүр ямар хичээл үзэх, аль номоор үзэхийг заана. 6а ангийн 10 хичээл бодит номтой. Бусад 13 ангийн мөрүүд улсын хөтөлбөрөөс түр бөглөгдсөн — сургууль баталгаажуулах ёстой.
A3: ЗАРИМ НЬ ОРСОН — дутууг нөхөх шаардлагатай
A5: Төлөв | B5: Ангийн код | C5: Хичээлийн код | D5: Анги | E5: Хичээл | F5: Номын код | G5: Номын нэр | H5: Эх сурвалж
A6: БОДИТ | B6: EJ-2627-1A | C6: ART | D6: 1а | E6: Дүрслэх урлаг | H6: Улсын хөтөлбөрөөс түр (батлагдаагүй)
A7: БОДИТ | B7: EJ-2627-1A | C7: DTECH | D7: 1а | E7: Дизайн технологи | H7: Улсын хөтөлбөрөөс түр (батлагдаагүй)
A8: БОДИТ | B8: EJ-2627-1A | C8: MATH | D8: 1а | E8: Математик | H8: Улсын хөтөлбөрөөс түр (батлагдаагүй)
A9: БОДИТ | B9: EJ-2627-1A | C9: MGL | D9: 1а | E9: Монгол хэл | H9: Улсын хөтөлбөрөөс түр (батлагдаагүй)
A10: БОДИТ | B10: EJ-2627-2A | C10: ART | D10: 2а | E10: Дүрслэх урлаг | H10: Улсын хөтөлбөрөөс түр (батлагдаагүй)
A11: БОДИТ | B11: EJ-2627-2A | C11: DTECH | D11: 2а | E11: Дизайн технологи | H11: Улсын хөтөлбөрөөс түр (батлагдаагүй)
A12: БОДИТ | B12: EJ-2627-2A | C12: MATH | D12: 2а | E12: Математик | H12: Улсын хөтөлбөрөөс түр (батлагдаагүй)
A13: БОДИТ | B13: EJ-2627-2A | C13: MGL | D13: 2а | E13: Монгол хэл | H13: Улсын хөтөлбөрөөс түр (батлагдаагүй)
A14: БОДИТ | B14: EJ-2627-3A | C14: ART | D14: 3а | E14: Дүрслэх урлаг | H14: Улсын хөтөлбөрөөс түр (батлагдаагүй)
A15: БОДИТ | B15: EJ-2627-3A | C15: DTECH | D15: 3а | E15: Дизайн технологи | H15: Улсын хөтөлбөрөөс түр (батлагдаагүй)
A16: БОДИТ | B16: EJ-2627-3A | C16: ENG | D16: 3а | E16: Англи хэл | H16: Улсын хөтөлбөрөөс түр (батлагдаагүй)
A17: БОДИТ | B17: EJ-2627-3A | C17: MATH | D17: 3а | E17: Математик | H17: Улсын хөтөлбөрөөс түр (батлагдаагүй)
... A31: БОДИТ | B31: EJ-2627-5A | C31: SCI | D31: 5а | E31: Байгалийн ухаан | H31: Улсын хөтөлбөрөөс түр (батлагдаагүй)
A32: БОДИТ | B32: EJ-2627-6A | C32: ART | D32: 6а | E32: Дүрслэх урлаг | F32: G06-ART-MN | G32: Дүрслэх урлаг VI–VII | H32: Бодит бүртгэл (номоор баталгаажсан)
A33: БОДИТ | B33: EJ-2627-6A | C33: DTECH | D33: 6а | E33: Дизайн технологи | F33: G06-DTECH-MN | G33: Дизайн технологи VI | H33: Бодит бүртгэл (номоор баталгаажсан)
A34: БОДИТ | B34: EJ-2627-6A | C34: ENG | D34: 6а | E34: Англи хэл | H34: Бодит бүртгэл (номоор баталгаажсан)
A35: БОДИТ | B35: EJ-2627-6A | C35: ETHICS | D35: 6а | E35: Иргэний ёс зүйн боловсрол | F35: G06-ETHICS-MN | G35: Иргэний ёс зүйн боловсрол VI | H35: Бодит бүртгэл (номоор баталгаажсан)
A36: БОДИТ | B36: EJ-2627-6A | C36: HIST | D36: 6а | E36: Түүх | F36: G06-HIST-MN | G36: Түүх VI | H36: Бодит бүртгэл (номоор баталгаажсан)
A37: БОДИТ | B37: EJ-2627-6A | C37: ICT | D37: 6а | E37: Мэдээллийн технологи | F37: G06-ICT-MN | G37: Мэдээллийн технологи VI | H37: Бодит бүртгэл (номоор баталгаажсан)
A38: БОДИТ | B38: EJ-2627-6A | C38: LIT | D38: 6а | E38: Уран зохиол | F38: G06-LIT-MN | G38: Уран зохиол VI | H38: Бодит бүртгэл (номоор баталгаажсан)
A39: БОДИТ | B39: EJ-2627-6A | C39: MATH | D39: 6а | E39: Математик | F39: G06-MATH-MN | G39: Математик VI | H39: Бодит бүртгэл (номоор баталгаажсан)
A40: БОДИТ | B40: EJ-2627-6A | C40: MGL | D40: 6а | E40: Монгол хэл | F40: G06-MGL-MN | G40: Монгол хэл VI | H40: Бодит бүртгэл (номоор баталгаажсан)
A41: БОДИТ | B41: EJ-2627-6A | C41: SCI | D41: 6а | E41: Байгалийн ухаан | F41: G06-SCI-MN | G41: Байгалийн ухаан VI | H41: Бодит бүртгэл (номоор баталгаажсан)
A42: БОДИТ | B42: EJ-2627-6A | C42: SCRIPT | D42: 6а | E42: Үндэсний бичиг | F42: G06-SCRIPT-MN | G42: Үндэсний бичиг VI | H42: Бодит бүртгэл (номоор баталгаажсан)
A43: БОДИТ | B43: EJ-2627-7A | C43: ART | D43: 7а | E43: Дүрслэх урлаг | H43: Улсын хөтөлбөрөөс түр (батлагдаагүй)
A44: БОДИТ | B44: EJ-2627-7A | C44: DTECH | D44: 7а | E44: Дизайн технологи | H44: Улсын хөтөлбөрөөс түр (батлагдаагүй)
A45: БОДИТ | B45: EJ-2627-7A | C45: ENG | D45: 7а | E45: Англи хэл | H45: Улсын хөтөлбөрөөс түр (батлагдаагүй)
A46: БОДИТ | B46: EJ-2627-7A | C46: ETHICS | D46: 7а | E46: Иргэний ёс зүйн боловсрол | H46: Улсын хөтөлбөрөөс түр (батлагдаагүй)
A47: БОДИТ | B47: EJ-2627-7A | C47: HIST | D47: 7а | E47: Түүх | H47: Улсын хөтөлбөрөөс түр (батлагдаагүй)
A48: БОДИТ | B48: EJ-2627-7A | C48: ICT | D48: 7а | E48: Мэдээллийн технологи | H48: Улсын хөтөлбөрөөс түр (батлагдаагүй)
A49: БОДИТ | B49: EJ-2627-7A | C49: LIT | D49: 7а | E49: Уран зохиол | H49: Улсын хөтөлбөрөөс түр (батлагдаагүй)
A50: БОДИТ | B50: EJ-2627-7A | C50: MATH | D50: 7а | E50: Математик | H50: Улсын хөтөлбөрөөс түр (батлагдаагүй)
A51: БОДИТ | B51: EJ-2627-7A | C51: MGL | D51: 7а | E51: Монгол хэл | H51: Улсын хөтөлбөрөөс түр (батлагдаагүй)
A52: БОДИТ | B52: EJ-2627-7A | C52: SCI | D52: 7а | E52: Байгалийн ухаан | H52: Улсын хөтөлбөрөөс түр (батлагдаагүй)
A53: БОДИТ | B53: EJ-2627-7A | C53: SCRIPT | D53: 7а | E53: Үндэсний бичиг | H53: Улсын хөтөлбөрөөс түр (батлагдаагүй)
A54: БОДИТ | B54: EJ-2627-7B | C54: ART | D54: 7б | E54: Дүрслэх урлаг | H54: Улсын хөтөлбөрөөс түр (батлагдаагүй)
...

Sheet 09 Номын сэдэв
A1: Номын сэдвийн задаргаа (★)
A2: Ном бүрийн бүлэг, сэдэв, хуудасны дугаар, аль улиралд үзэхийг заана. Математик VI (72 сэдэв) болон Монгол хэл VI (27 сэдэв) орсон. Үлдсэн 9 номынх ОРООГҮЙ — сүүлийн 4 шар мөр нь юу хэрэгтэйг харуулсан жишээ.
A3: ЗАРИМ НЬ ОРСОН — дутууг нөхөх шаардлагатай
A5: Төлөв | B5: Номын код | C5: Ном | D5: Дараалал | E5: Бүлэг/дугаар | F5: Сэдвийн нэр | G5: Хуудас эхлэх | H5: Хуудас дуусах | I5: Улирал
A6: БОДИТ | B6: G06-MATH-MN | C6: Математик VI | D6: 1 | E6: I.1 | F6: Бүхэл тоонуудыг жиших | G6: 5 | H6: 6 | I6: 1
A7: БОДИТ | B7: G06-MATH-MN | C7: Математик VI | D7: 2 | E7: I.2 | F7: Бүхэл тооны нэмэх, хасах үйлдэл | G7: 7 | H7: 9 | I7: 1
A8: БОДИТ | B8: G06-MATH-MN | C8: Математик VI | D8: 3 | E8: I.3 | F8: Бүхэл тооны үржүүлэх, хуваах үйлдэл | G8: 10 | H8: 11 | I8: 1
A9: БОДИТ | B9: G06-MATH-MN | C9: Математик VI | D9: 4 | E9: I.4 | F9: 4, 6 ба 8-д хуваагдах тооны шинж | G9: 12 | H9: 13 | I9: 1
A10: БОДИТ | B10: G06-MATH-MN | C10: Математик VI | D10: 5 | E10: I.5 | F10: Ерөнхий хуваагч ба хамгийн их ерөнхий хуваагч | G10: 14 | H10: 14 | I10: 1
A11: БОДИТ | B11: G06-MATH-MN | C11: Математик VI | D11: 6 | E11: I.6 | F11: Ерөнхий хуваагдагч ба хамгийн бага ерөнхий хуваагдагч | G11: 15 | H11: 16 | I11: 1
A12: БОДИТ | B12: G06-MATH-MN | C12: Математик VI | D12: 7 | E12: I.7 | F12: Анхны тоо | G12: 17 | H12: 17 | I12: 1
A13: БОДИТ | B13: G06-MATH-MN | C13: Математик VI | D13: 8 | E13: I.8 | F13: Тооны квадрат зэрэг ба квадрат язгуур | G13: 18 | H13: 19 | I13: 1
A14: БОДИТ | B14: G06-MATH-MN | C14: Математик VI | D14: 9 | E14: I.9 | F14: Хэллэг | G14: 20 | H14: 20 | I14: 1
A15: БОДИТ | B15: G06-MATH-MN | C15: Математик VI | D15: 10 | E15: I.10 | F15: Олонлог | G15: 21 | H15: 22 | I15: 1
A16: БОДИТ | B16: G06-MATH-MN | C16: Математик VI | D16: 11 | E16: II.1 | F16: Тоог жиших, эрэмбэлэх | G16: 23 | H16: 24 | I16: 1
A17: БОДИТ | B17: G06-MATH-MN | C17: Математик VI | D17: 12 | E17: II.2 | F17: Тоог тоймлох | G17: 25 | H17: 28 | I17: 1
... A108: ЖИШЭЭ | B108: G06-SCI-MN | C108: Байгалийн ухаан VI | D108: 2 | E108: I.2 | F108: Ургамлын шим тэжээл | G108: 13 | H108: 18 | I108: 1
A110: Улирал = 1, 2 эсвэл 3. Сэдэв бүрийг аль улиралд үзэхийг заавал тэмдэглэнэ — «одоо хаана явж байна» болон «энэ улиралд юу багтах» үүнээс тооцогдоно.

Sheet 10 Улирал
A1: Улирлын хуваарь (★)
A2: Хичээлийн жилийн 4 улирал. ОГНОО НЬ ТААМАГ — сургуулийн амралтын хуанли хараахан ирээгүй тул ердийн хуваарийг түр тавьсан. «Одоо аль улирал» гэдэг эдгээр огноон дээр тооцогддог.
A3: ЗАРИМ НЬ ОРСОН — дутууг нөхөх шаардлагатай
A5: Төлөв | B5: Хичээлийн жил | C5: Улирал | D5: Нэр | E5: Эхлэх огноо | F5: Дуусах огноо | G5: Хоног | H5: Тэмдэглэл
A6: ЖИШЭЭ | B6: 2026-2027 | C6: 1 | D6: I улирал (түр огноо) | E6: 46266 | F6: 46326 | G6: =$F6-$E6+1 | H6: Түр таамаг огноо — жинхэнэ хуанли ирэхэд солино
A7: ЖИШЭЭ | B7: 2026-2027 | C7: 2 | D7: II улирал (түр огноо) | E7: 46335 | F7: 46387 | G7: =$F7-$E7+1 | H7: Түр таамаг огноо — жинхэнэ хуанли ирэхэд солино
A8: ЖИШЭЭ | B8: 2026-2027 | C8: 3 | D8: III улирал (түр огноо) | E8: 46398 | F8: 46466 | G8: =$F8-$E8+1 | H8: Түр таамаг огноо — жинхэнэ хуанли ирэхэд солино
A9: ЖИШЭЭ | B9: 2026-2027 | C9: 4 | D9: IV улирал (түр огноо) | E9: 46475 | F9: 46543 | G9: =$F9-$E9+1 | H9: Түр таамаг огноо — жинхэнэ хуанли ирэхэд солино
A11: Хэрэгтэй зүйл: 4 улирлын жинхэнэ эхлэх, дуусах огноо ба амралтын хуваарь.

Sheet 11 Ангийн одоогийн сэдэв
A1: Анги одоо аль сэдэв дээр яваа
A2: Багш «манай анги одоо энэ сэдэв дээр байна» гэж заана, сурагчид шууд хардаг. Энэ нь хуанлиас тооцогддоггүй: хоцорсон анги эрт улирлын сэдэв дээр байж болох бөгөөд тэр нь буруу биш.
A3: ЗАРИМ НЬ ОРСОН — дутууг нөхөх шаардлагатай
A5: Төлөв | B5: Ангийн код | C5: Анги | D5: Хичээлийн код | E5: Хичээл | F5: Сэдвийн дугаар | G5: Сэдвийн нэр | H5: Хуудас | I5: Улирал | J5: Эхэлсэн огноо | K5: Тэмдэглэсэн багш
A6: БОДИТ | B6: EJ-2627-6A | C6: 6а | D6: MATH | E6: Математик | F6: II.4 | G6: Аравтын бутархайн нэмэх, хасах үйлдэл | H6: 30–31 | I6: 1 | J6: 46287 | K6: Б.Амартүвшин
A7: ЖИШЭЭ | B7: EJ-2627-6A | C7: 6а | D7: MGL | E7: Монгол хэл | F7: I.3 | G7: Жинхэнэ нэрийн хэл зүйн шинж, найруулгын үүргийг тодорхойлох | H7: 12–20 | I7: 1 | J7: 46286 | K7: Н.Нансал
A8: ЖИШЭЭ | B8: EJ-2627-7A | C8: 7а | D8: MATH | E8: Математик | G8: Номын сэдэв ороогүй тул сэдэв заах боломжгүй
A10: Зөвхөн номын сэдэв орсон хичээлд заах боломжтой. Тиймээс «08 Номын сэдэв»-ийг гүйцээх нь эхний алхам.

Sheet 12 Хичээлийн хуваарь
A1: Хичээлийн хуваарь (★)
A2: Аль анги, хэзээ, ямар хичээл, хэн заах, ямар сэдэв үзэхийг заана. БААЗАД ХООСОН. Доорх нь 6а ангийн нэг долоо хоногийн жишээ — сэдвүүдийг Математик VI номын бодит задаргаанаас авав.
A3: ХООСОН — бүхэлдээ сургуулиас авах ёстой
A5: Төлөв | B5: Ангийн код | C5: Анги | D5: Огноо | E5: Гараг | F5: Хичээлийн дугаар | G5: Хичээлийн код | H5: Хичээл | I5: Багш | J5: Үзэх сэдэв | K5: Хуудас | L5: Танхим | M5: Тэмдэглэл
A6: ЖИШЭЭ | B6: EJ-2627-6A | C6: 6а | D6: 46286 | E6: Даваа | F6: 1 | G6: MATH | H6: Математик | I6: Б.Буянзаяа | J6: II.4 Аравтын бутархайн нэмэх, хасах үйлдэл | K6: 30–31 | L6: 201
A7: ЖИШЭЭ | B7: EJ-2627-6A | C7: 6а | D7: 46286 | E7: Даваа | F7: 2 | G7: MGL | H7: Монгол хэл | I7: Н.Нансал | J7: I.3 Жинхэнэ нэрийн хэл зүйн шинж | K7: 12–20 | L7: 201
A8: ЖИШЭЭ | B8: EJ-2627-6A | C8: 6а | D8: 46286 | E8: Даваа | F8: 3 | G8: ENG | H8: Англи хэл | I8: Э.Дуламсүрэн | J8: Unit 2 — Daily routines | L8: 305
A9: ЖИШЭЭ | B9: EJ-2627-6A | C9: 6а | D9: 46287 | E9: Мягмар | F9: 1 | G9: SCI | H9: Байгалийн ухаан | I9: Б.Отгонбулаг | J9: I.1 Амьд биетийн эрхтэн тогтолцоо | K9: 6–12 | L9: 204
A10: ЖИШЭЭ | B10: EJ-2627-6A | C10: 6а | D10: 46287 | E10: Мягмар | F10: 2 | G10: MATH | H10: Математик | I10: Б.Буянзаяа | J10: II.5 Аравтын бутархайг бүхэл тоогоор үржүүлэх | K10: 32–35 | L10: 201
A11: ЖИШЭЭ | B11: EJ-2627-6A | C11: 6а | D11: 46287 | E11: Мягмар | F11: 3 | G11: HIST | H11: Түүх | I11: Б.Амартүвшин | J11: I.1 Монголын эртний түүх | K11: 5–9 | L11: 108
A12: ЖИШЭЭ | B12: EJ-2627-6A | C12: 6а | D12: 46288 | E12: Лхагва | F12: 1 | G12: LIT | H12: Уран зохиол | I12: Т.Эрдэнээ | J12: I.1 Ардын аман зохиол | K12: 4–11 | L12: 201
A13: ЖИШЭЭ | B13: EJ-2627-6A | C13: 6а | D13: 46288 | E13: Лхагва | F13: 2 | G13: MATH | H13: Математик | I13: Б.Буянзаяа | J13: II.6 Аравтын бутархайн үржүүлэх, хуваах | K13: 36–38 | L13: 201
A14: ЖИШЭЭ | B14: EJ-2627-6A | C14: 6а | D14: 46289 | E14: Пүрэв | F14: 1 | G14: ART | H14: Дүрслэх урлаг | I14: Э.Номуундарь | J14: I.1 Өнгөний зохицол | K14: 5–10 | L14: 110
A15: ЖИШЭЭ | B15: EJ-2627-6A | C15: 6а | D15: 46289 | E15: Пүрэв | F15: 2 | G15: ETHICS | H15: Иргэний ёс зүйн боловсрол | I15: А.Мөнхнаран | J15: I.1 Иргэний үүрэг | K15: 4–9 | L15: 201
A16: ЖИШЭЭ | B16: EJ-2627-6A | C16: 6а | D16: 46290 | E16: Баасан | F16: 1 | G16: MATH | H16: Математик | I16: Б.Буянзаяа | J16: II.7 Хялбар аргаар тооцоолох | K16: 39 | L16: 201
A17: ЖИШЭЭ | B17: EJ-2627-6A | C17: 6а | D17: 46290 | E17: Баасан | F17: 2 | G17: DTECH | H17: Дизайн технологи | I17: Э.Номуундарь | J17: I.1 Материал судлал | K17: 5–12 | L17: 110
A19: Хэрэгтэй зүйл: анги бүрийн долоо хоногийн хуваарь — гараг, хичээлийн дугаар, хичээл, багш, танхим. Энэ нь «Өнөөдрийн хичээл» дэлгэцийн үндэс.

Sheet 13 Хичээлийн агуулга
A1: Нэг хичээлийн агуулга
A2: Сурагч дэлгэцээс уншдаг агуулга: зорилт, тайлбар, жишээ, бие даалт. БААЗАД ХООСОН. Нэг хичээл нь номын нэг сэдэвтэй холбогдоно.
A3: ХООСОН — бүхэлдээ сургуулиас авах ёстой
A5: Төлөв | B5: Агуулгын код | C5: Хичээлийн код | D5: Хичээл | E5: Ангийн код | F5: Анги | G5: Номын сэдэв | H5: Суралцахуйн зорилт | I5: Тайлбар | J5: Жишээ | K5: Бие даалт | L5: Хугацаа (мин) | M5: Батлагдсан эсэх
A6: ЖИШЭЭ | B6: L-6A-MATH-001 | C6: MATH | D6: Математик | E6: EJ-2627-6A | F6: 6а | G6: II.4 Аравтын бутархайн нэмэх, хасах үйлдэл | H6: Аравтын бутархай тоонуудыг багана хэлбэрээр нэмж, хасаж сурах | I6: Таслалыг таслалынх нь доор бичээд, дараа нь бүхэл тоо шиг нэмнэ. | J6: 3.45 + 2.7 = 6.15 | K6: Номын 31-р хуудасны 1–6 дасгал | L6: 40 | M6: Ноорог
A7: ЖИШЭЭ | B7: L-6A-MATH-002 | C7: MATH | D7: Математик | E7: EJ-2627-6A | F7: 6а | G7: II.5 Аравтын бутархайг бүхэл тоогоор үржүүлэх | H7: Аравтын бутархайг бүхэл тоогоор үржүүлж, хуваах | I7: Эхлээд таслалгүй үржүүлээд, дараа нь таслалыг зөв байранд тавина. | J7: 2.4 × 3 = 7.2 | K7: Номын 34–35-р хуудасны дасгал | L7: 40 | M7: Ноорог
A8: ЖИШЭЭ | B8: L-6A-MGL-001 | C8: MGL | D8: Монгол хэл | E8: EJ-2627-6A | F8: 6а | G8: I.3 Жинхэнэ нэрийн хэл зүйн шинж | H8: Жинхэнэ нэрийг таних, найруулгад гүйцэтгэх үүргийг тайлбарлах | I8: Жинхэнэ нэр нь юмс үзэгдлийн нэрийг заана. | J8: Уул, ном, багш — бүгд жинхэнэ нэр | K8: Номын 18–20-р хуудасны даалгавар | L8: 40 | M8: Ноорог
A10: Агуулгыг багш бичиж, менежер батална гэж тохирсон.

Sheet 14 Чадвар
A1: Чадвар (★)
A2: Чадвар нь «сурагч юу чаддаг болох ёстой вэ» гэдгийг заана. Ном биш, ХИЧЭЭЛ + АНГИ дээр тодорхойлогддог — учир нь ном солигдож болно, чадвар үлддэг. Нэг чадварыг ихэвчлэн номын хэд хэдэн сэдвээр дамжуулж заана. БААЗАД ХООСОН.
A3: ХООСОН — бүхэлдээ сургуулиас авах ёстой
A5: Төлөв | B5: Чадварын код | C5: Хичээлийн код | D5: Хичээл | E5: Анги | F5: Чадварын нэр | G5: Суралцахуйн үр дүн | H5: Хүндрэл (1-5) | I5: Батлагдсан эсэх
A6: ЖИШЭЭ | B6: MATH-6-01 | C6: MATH | D6: Математик | E6: 6 | F6: Бүхэл тооны нэмэх, хасах, үржүүлэх, хуваах | G6: Бүхэл тоон дээр дөрвөн үйлдлийг алдаагүй гүйцэтгэх | H6: 1 | I6: Ноорог
A7: ЖИШЭЭ | B7: MATH-6-02 | C7: MATH | D7: Математик | E7: 6 | F7: Хуваагдах шинж, ЕИХХ, ЕБХ | G7: Тоо хуваагдах эсэхийг тодорхойлж, ерөнхий хуваагчийг олох | H7: 2 | I7: Ноорог
A8: ЖИШЭЭ | B8: MATH-6-03 | C8: MATH | D8: Математик | E8: 6 | F8: Аравтын бутархайг нэмэх, хасах | G8: Аравтын бутархай тоонуудыг багана хэлбэрээр нэмж, хасах | H8: 2 | I8: Ноорог
A9: ЖИШЭЭ | B9: MATH-6-04 | C9: MATH | D9: Математик | E9: 6 | F9: Аравтын бутархайг үржүүлэх, хуваах | G9: Аравтын бутархайг бүхэл тоо болон бутархайгаар үржүүлж, хуваах | H9: 3 | I9: Ноорог
A10: ЖИШЭЭ | B10: MATH-6-05 | C10: MATH | D10: Математик | E10: 6 | F10: Энгийн бутархайг хураах, жиших | G10: Энгийн бутархайг хурааж, хооронд нь жиших | H10: 2 | I10: Ноорог
A11: ЖИШЭЭ | B11: MGL-6-01 | C11: MGL | D11: Монгол хэл | E11: 6 | F11: Жинхэнэ нэрийн хэл зүйн шинжийг тодорхойлох | G11: Өгүүлбэрээс жинхэнэ нэрийг ялгаж, үүргийг тайлбарлах | H11: 2 | I11: Ноорог
A13: Англи хэл дээр чадвар нь ангид биш CEFR түвшинд (A1–C2) наалддаг. Тиймээс «Анги» багана хоосон байж, оронд нь түвшин бичигдэнэ.

Sheet 15 Чадварын урьдач нөхцөл
A1: Чадвар ↔ чадвар (урьдач нөхцөл)
A2: Аль чадварыг эзэмшихийн өмнө юуг мэдсэн байх ёстойг заана. Сурагч чадвараа эзэмшээгүй үед систем энэ гинжээр буцаж «юуг нөхөх ёстой»-г олдог. БААЗАД ХООСОН.
A3: ХООСОН — бүхэлдээ сургуулиас авах ёстой
A5: Төлөв | B5: Чадварын код | C5: Чадвар | D5: Урьдач чадварын код | E5: Урьдач чадвар | F5: Төрөл | G5: Тайлбар
A6: ЖИШЭЭ | B6: MATH-6-03 | C6: Аравтын бутархайг нэмэх, хасах | D6: MATH-6-01 | E6: Бүхэл тооны нэмэх, хасах, үржүүлэх, хуваах | F6: ЗААВАЛ | G6: Бүхэл тооны үйлдэл мэдэхгүй бол бутархай нэмэх боломжгүй
A7: ЖИШЭЭ | B7: MATH-6-04 | C7: Аравтын бутархайг үржүүлэх, хуваах | D7: MATH-6-03 | E7: Аравтын бутархайг нэмэх, хасах | F7: ЗААВАЛ
A8: ЖИШЭЭ | B8: MATH-6-02 | C8: Хуваагдах шинж, ЕИХХ, ЕБХ | D8: MATH-6-01 | E8: Бүхэл тооны нэмэх, хасах, үржүүлэх, хуваах | F8: ЗААВАЛ
A9: ЖИШЭЭ | B9: MATH-6-03 | C9: Аравтын бутархайг нэмэх, хасах | D9: MATH-6-05 | E9: Энгийн бутархайг хураах, жиших | F9: ЗӨВЛӨМЖ | G9: Хамт эзэмшвэл ойлголт бэхжинэ, гэхдээ заавал биш
A11: Төрөл: ЗААВАЛ (REQUIRED), ЗӨВЛӨМЖ (RECOMMENDED), ХОЛБООТОЙ (RELATED). «Хувийн бэлтгэл»-ийн нөхөх ажил энэ гинжээс автоматаар тодорхойлогдоно.

Sheet 16 Сэдэв-чадвар-ном
A1: Чадвар ↔ номын сэдэв холбоос (★)
A2: Чадварыг номын аль хэсгээр заадгийг холбоно. Нэг чадвар олон сэдэвт, нэг сэдэв олон чадварт харьяалагдаж болно. Баазад энэ нь гурван хүснэгтээр хийгддэг: content_nodes (агуулгын зангилаа), content_skill_maps (зангилаа↔чадвар), content_source_alignments (зангилаа↔ном, хуудас). Энд гурвыг нэг харагдацад нэгтгэв. БААЗАД ХООСОН.
A3: ХООСОН — бүхэлдээ сургуулиас авах ёстой
A5: Төлөв | B5: Агуулгын код | C5: Агуулгын нэр | D5: Чадварын код | E5: Чадвар | F5: Үндсэн эсэх | G5: Номын код | H5: Сэдвийн дугаар | I5: Сэдвийн нэр | J5: Хуудас эхлэх | K5: Хуудас дуусах
A6: ЖИШЭЭ | B6: T-MATH-6-INT | C6: Бүхэл тоо ба үйлдэл | D6: MATH-6-01 | E6: Бүхэл тооны нэмэх, хасах, үржүүлэх, хуваах | F6: Тийм | G6: G06-MATH-MN | H6: I.2 | I6: Бүхэл тооны нэмэх, хасах үйлдэл | J6: 7 | K6: 9
A7: ЖИШЭЭ | B7: T-MATH-6-DIV | C7: Хуваагдах шинж | D7: MATH-6-02 | E7: Хуваагдах шинж, ЕИХХ, ЕБХ | F7: Тийм | G7: G06-MATH-MN | H7: I.4 | I7: 4, 6 ба 8-д хуваагдах тооны шинж | J7: 12 | K7: 13
A8: ЖИШЭЭ | B8: T-MATH-6-DEC | C8: Аравтын бутархайн үйлдэл | D8: MATH-6-03 | E8: Аравтын бутархайг нэмэх, хасах | F8: Тийм | G8: G06-MATH-MN | H8: II.4 | I8: Аравтын бутархайн нэмэх, хасах үйлдэл | J8: 30 | K8: 31
A9: ЖИШЭЭ | B9: T-MATH-6-DEC | C9: Аравтын бутархайн үйлдэл | D9: MATH-6-04 | E9: Аравтын бутархайг үржүүлэх, хуваах | F9: Үгүй | G9: G06-MATH-MN | H9: II.5 | I9: Аравтын бутархайг бүхэл тоогоор үржүүлэх, бүхэл тоонд хуваах | J9: 32 | K9: 35
A10: ЖИШЭЭ | B10: T-MATH-6-FRAC | C10: Энгийн бутархай | D10: MATH-6-05 | E10: Энгийн бутархайг хураах, жиших | F10: Тийм | G10: G06-MATH-MN | H10: II.8 | I10: Энгийн бутархайг хураах, жиших | J10: 40 | K10: 42
A11: ЖИШЭЭ | B11: T-MGL-6-NOUN | C11: Жинхэнэ нэр | D11: MGL-6-01 | E11: Жинхэнэ нэрийн хэл зүйн шинжийг тодорхойлох | F11: Тийм | G11: G06-MGL-MN | H11: I.3 | I11: Жинхэнэ нэрийн хэл зүйн шинж, найруулгын үүргийг тодорхойлох | J11: 12 | K11: 20
A13: «Үндсэн эсэх» = энэ сэдэв тухайн чадварыг ҮНДСЭНД нь заадаг эсэх. Нэг зангилаанд зөвхөн нэг үндсэн чадвар байна.

Sheet 17 Асуултын сан
A1: Асуултын сан (★ ЧАДВАР БА СЭДЭВ ХОЁУЛАНД ХОЛБОГДОНО)
A2: Асуулт бүр ХОЁР зүйлд заана: аль ЧАДВАРЫГ хэмжиж байгаа, номын аль СЭДВИЙН дараа асуух вэ. Энэ хоёр байхгүй бол асуултыг зөв газар нь тавьж чадахгүй: чадваргүй бол ахиц хэмжигдэхгүй, сэдэвгүй бол нэг чадварын бүх асуулт эхний өдрөөс харагдана. БААЗАД ХООСОН.
A3: ХООСОН — бүхэлдээ сургуулиас авах ёстой
A5: Төлөв | B5: Асуултын код | C5: Хичээлийн код | D5: Анги | E5: Чадварын код | F5: Чадвар | G5: Сэдвийн дугаар | H5: Сэдвийн нэр | I5: Хуудас эхлэх | J5: Хуудас дуусах | K5: Дараалал | L5: Асуулт | M5: Төрөл | N5: Нийт оноо | O5: Үнэлэх заавар | P5: Батлагдсан эсэх
A6: ЖИШЭЭ | B6: Q-M6-0301 | C6: MATH | D6: 6 | E6: MATH-6-03 | F6: Аравтын бутархайг нэмэх, хасах | G6: II.4 | H6: Аравтын бутархайн нэмэх, хасах үйлдэл | I6: 30 | J6: 31 | K6: 1 | L6: 3.45 + 2.7 үйлдлийн үр дүнг ол. | M6: Сонголттой | N6: 1 | O6: Зөв хариулт 1 оноо. Хэсэгчилсэн оноо байхгүй. | P6: Ноорог
A7: ЖИШЭЭ | B7: Q-M6-0302 | C7: MATH | D7: 6 | E7: MATH-6-03 | F7: Аравтын бутархайг нэмэх, хасах | G7: II.4 | H7: Аравтын бутархайн нэмэх, хасах үйлдэл | I7: 30 | J7: 31 | K7: 2 | L7: 8.2 − 5.47 үйлдлийн үр дүнг ол. | M7: Сонголттой | N7: 1 | O7: Зөв хариулт 1 оноо. | P7: Ноорог
A8: ЖИШЭЭ | B8: Q-M6-0303 | C8: MATH | D8: 6 | E8: MATH-6-03 | F8: Аравтын бутархайг нэмэх, хасах | G8: II.4 | H8: Аравтын бутархайн нэмэх, хасах үйлдэл | I8: 30 | J8: 31 | K8: 3 | L8: Дэлгүүрээс 2.5 кг алим, 1.75 кг жүрж авав. Нийт хэдэн кг жимс авсан бэ? Бодолтыг бич. | M8: Нээлттэй бодлого | N8: 2 | O8: Бодолт зөв бичигдсэн бол 1 оноо, хариу зөв бол нэмж 1 оноо (нийт 2). | P8: Ноорог
A9: ЖИШЭЭ | B9: Q-M6-0401 | C9: MATH | D9: 6 | E9: MATH-6-04 | F9: Аравтын бутархайг үржүүлэх, хуваах | G9: II.5 | H9: Аравтын бутархайг бүхэл тоогоор үржүүлэх, бүхэл тоонд хуваах | I9: 32 | J9: 35 | K9: 1 | L9: 2.4 × 3 үйлдлийн үр дүнг ол. | M9: Сонголттой | N9: 1 | O9: Зөв хариулт 1 оноо. | P9: Ноорог
A10: ЖИШЭЭ | B10: Q-M6-0101 | C10: MATH | D10: 6 | E10: MATH-6-01 | F10: Бүхэл тооны нэмэх, хасах, үржүүлэх, хуваах | G10: I.2 | H10: Бүхэл тооны нэмэх, хасах үйлдэл | I10: 7 | J10: 9 | K10: 1 | L10: 345 + 278 үйлдлийн үр дүнг ол. | M10: Сонголттой | N10: 1 | O10: Зөв хариулт 1 оноо. | P10: Ноорог
A11: ЖИШЭЭ | B11: Q-MGL6-0101 | C11: MGL | D11: 6 | E11: MGL-6-01 | F11: Жинхэнэ нэрийн хэл зүйн шинжийг тодорхойлох | G11: I.3 | H11: Жинхэнэ нэрийн хэл зүйн шинж, найруулгын үүргийг тодорхойлох | I11: 12 | J11: 20 | K11: 1 | L11: «Багш сурагчдад ном өглөө» өгүүлбэрээс жинхэнэ нэрийг бүгдийг нь ол. | M11: Нээлттэй | N11: 2 | O11: Гурван жинхэнэ нэрийг олбол 2 оноо, хоёрыг олбол 1 оноо. | P11: Ноорог
A13: Сэдвийн багана хоосон байж болно — тэр үед асуулт тухайн чадварын БҮХ өдөр харагдана. Энэ нь импорт сэдвийг заагаагүй үед л тохиолдох ёстой.

Sheet 18 Асуултын сонголт
A1: Сонголттой асуултын хариултууд
A2: Сонголттой асуулт бүрийн хувилбарууд, аль нь зөв болох. Нээлттэй асуултад мөр байхгүй — тэдгээрийг багш «Үнэлэх заавар»-аар гараар үнэлнэ. БААЗАД ХООСОН.
A3: ХООСОН — бүхэлдээ сургуулиас авах ёстой
A5: Төлөв | B5: Асуултын код | C5: Хувилбар | D5: Хариултын текст | E5: Зөв эсэх | F5: Дараалал
A6: ЖИШЭЭ | B6: Q-M6-0301 | C6: А | D6: 6.15 | E6: ТИЙМ | F6: 1
A7: ЖИШЭЭ | B7: Q-M6-0301 | C7: Б | D7: 5.15 | E7: үгүй | F7: 2
A8: ЖИШЭЭ | B8: Q-M6-0301 | C8: В | D8: 6.05 | E8: үгүй | F8: 3
A9: ЖИШЭЭ | B9: Q-M6-0301 | C9: Г | D9: 3.72 | E9: үгүй | F9: 4
A10: ЖИШЭЭ | B10: Q-M6-0302 | C10: А | D10: 2.73 | E10: ТИЙМ | F10: 1
A11: ЖИШЭЭ | B11: Q-M6-0302 | C11: Б | D11: 3.73 | E11: үгүй | F11: 2
A12: ЖИШЭЭ | B12: Q-M6-0302 | C12: В | D12: 2.83 | E12: үгүй | F12: 3
A13: ЖИШЭЭ | B13: Q-M6-0302 | C13: Г | D13: 3.27 | E13: үгүй | F13: 4
A14: ЖИШЭЭ | B14: Q-M6-0401 | C14: А | D14: 7.2 | E14: ТИЙМ | F14: 1
A15: ЖИШЭЭ | B15: Q-M6-0401 | C15: Б | D15: 6.2 | E15: үгүй | F15: 2
A16: ЖИШЭЭ | B16: Q-M6-0401 | C16: В | D16: 72 | E16: үгүй | F16: 3
A17: ЖИШЭЭ | B17: Q-M6-0401 | C17: Г | D17: 0.72 | E17: үгүй | F17: 4
... A21: ЖИШЭЭ | B21: Q-M6-0101 | C21: Г | D21: 633 | E21: үгүй | F21: 4
A23: Q-M6-0303 болон Q-MGL6-0101 нь нээлттэй асуулт тул энд байхгүй — жагсаалт бүрэн байх албагүй гэдгийг харуулах зорилготой.

Sheet 19 Дасгал даалгавар
A1: Дасгал, даалгавар
A2: Чадвар эзэмшүүлэхэд ажиллуулах дасгалууд. Түвшнээр (СУУРЬ / ҮНДСЭН / АХИСАН) эрэмбэлэгдэж, «дараагийн» болон «давтах» даалгавраар гинжлэгдэнэ — сурагч алдвал давтах руу, чадвал дараагийнх руу шилжинэ. БААЗАД ХООСОН.
A3: ХООСОН — бүхэлдээ сургуулиас авах ёстой
A5: Төлөв | B5: Даалгаврын код | C5: Чадварын код | D5: Чадвар | E5: Урьдач чадвар | F5: Түвшин | G5: Хүндрэл | H5: Төрөл | I5: Асуулт | J5: Оноо | K5: Хугацаа (мин) | L5: Дараагийн даалгавар | M5: Давтах даалгавар
A6: ЖИШЭЭ | B6: T-M6-03-01 | C6: MATH-6-03 | D6: Аравтын бутархайг нэмэх, хасах | E6: MATH-6-01 | F6: СУУРЬ | G6: 1 | H6: Багана хэлбэрээр нэмэх дасгал | I6: 4.5 + 3.2 = ? | J6: 1.5 | K6: 5 | L6: T-M6-03-02
A7: ЖИШЭЭ | B7: T-M6-03-02 | C7: MATH-6-03 | D7: Аравтын бутархайг нэмэх, хасах | F7: ҮНДСЭН | G7: 2 | H7: Өөр өөр оронтой бутархай нэмэх | I7: 12.75 + 3.4 = ? | J7: 2 | K7: 8 | L7: T-M6-03-03 | M7: T-M6-03-01
A8: ЖИШЭЭ | B8: T-M6-03-03 | C8: MATH-6-03 | D8: Аравтын бутархайг нэмэх, хасах | F8: АХИСАН | G8: 3 | H8: Хэрэглээний бодлого | I8: Гурван дэлгүүрт 2.35, 1.8, 4.05 кг жимс байв. Нийт хэд вэ? | J8: 3 | K8: 12 | M8: T-M6-03-02
A9: ЖИШЭЭ | B9: T-M6-01-01 | C9: MATH-6-01 | D9: Бүхэл тооны нэмэх, хасах, үржүүлэх, хуваах | F9: СУУРЬ | G9: 1 | H9: Бүхэл тоон дээр дөрвөн үйлдэл | I9: 345 + 278 = ? | J9: 1 | K9: 5 | L9: T-M6-01-02
A11: Энэ нь «Хувийн ажил» хуудастай хамт ажиллана: сурагчид оногдох нөхөх даалгаврыг эндээс сонгоно.

Sheet 20 Эзэмшилт шалгах
A1: Эзэмшилт шалгах асуулт
A2: «Энэ чадварыг эзэмшсэн үү» гэдгийг шийдэх асуултууд. Энгийн шалгалтаас ялгаатай нь ТЭНЦСЭН / ХАГАС / УНАСАН тохиолдол бүрд ЮУ ХИЙХИЙГ заасан байдаг — систем түүгээр нь дараагийн алхмыг сонгоно. БААЗАД ХООСОН.
A3: ХООСОН — бүхэлдээ сургуулиас авах ёстой
A5: Төлөв | B5: Кодын дугаар | C5: Чадварын код | D5: Чадвар | E5: Дараалал | F5: Төрөл | G5: Асуулт | H5: Зөв хариулт | I5: Оноо | J5: Тэнцэх дүрэм | K5: Тэнцвэл | L5: Хагас тэнцвэл | M5: Унавал
A6: ЖИШЭЭ | B6: MC-M6-03-1 | C6: MATH-6-03 | D6: Аравтын бутархайг нэмэх, хасах | E6: 1 | F6: Богино хариулт | G6: 12.75 + 3.4 = ? | H6: 16.15 | I6: 2 | J6: 2/2 оноо авбал тэнцсэн | K6: MATH-6-04 руу шилжинэ | L6: Нэмэлт дасгал T-M6-03-02 өгнө | M6: MATH-6-01 руу буцаж нөхнө
A7: ЖИШЭЭ | B7: MC-M6-03-2 | C7: MATH-6-03 | D7: Аравтын бутархайг нэмэх, хасах | E7: 2 | F7: Хэрэглээний бодлого | G7: 2.5 кг ба 1.75 кг жимсний нийлбэрийг ол. | H7: 4.25 кг | I7: 2 | J7: 2/2 оноо авбал тэнцсэн | K7: Эзэмшсэн гэж тэмдэглэнэ | L7: Дахин нэг бодлого өгнө | M7: Багштай ярина
A8: ЖИШЭЭ | B8: MC-M6-01-1 | C8: MATH-6-01 | D8: Бүхэл тооны нэмэх, хасах, үржүүлэх, хуваах | E8: 1 | F8: Богино хариулт | G8: 345 + 278 = ? | H8: 623 | I8: 1 | J8: 1/1 оноо авбал тэнцсэн | K8: MATH-6-03 руу шилжинэ | L8: — | M8: Бага ангийн агуулга давтана
A10: Сорилыг нэг л удаа өгдөг гэж тохирсон тул нэг цэвэр оролдлого эзэмшсэнд тооцогдоно.

Sheet 21 Шалгалт
A1: Шалгалтын хуудас (★)
A2: Нэг шалгалт = нэг мөр. Ангийн код хоосон бол тухайн ангийн бүх анги өгнө. Улирлыг тусад нь бичихгүй — огноо нь аль улиралд багтахаас тодорхойлогдоно, хоёр газар бичвэл зөрөх эрсдэлтэй. Тэнцэх оноог хувиар хадгална: асуулт нэмэгдэхэд нийт оноо өөрчлөгддөг тул тогтмол оноо утгаа алддаг. БААЗАД ХООСОН.
A3: ХООСОН — бүхэлдээ сургуулиас авах ёстой
A5: Төлөв | B5: Шалгалтын код | C5: Төрлийн код | D5: Төрөл | E5: Хичээлийн код | F5: Хичээл | G5: Ангийн код | H5: Анги | I5: Шалгалтын нэр | J5: Огноо | K5: Тэнцэх хувь | L5: Заавар
A6: ЖИШЭЭ | B6: EX-6A-MATH-U1 | C6: UNIT | D6: Нэгж хичээлийн шалгалт | E6: MATH | F6: Математик | G6: EJ-2627-6A | H6: 6а | I6: Математик VI — I бүлгийн шалгалт | J6: 46300 | K6: 0.6 | L6: 20 минут. Тооны машин хэрэглэхгүй.
A7: ЖИШЭЭ | B7: EX-6A-MATH-T1 | C7: TERM | D7: Улирлын шалгалт | E7: MATH | F7: Математик | G7: EJ-2627-6A | H7: 6а | I7: Математик VI — I улирлын шалгалт | J7: 46323 | K7: 0.6 | L7: 45 минут. I улирлын 26 сэдвийг бүхэлд нь хамарна.
A8: ЖИШЭЭ | B8: EX-6A-MGL-U1 | C8: UNIT | D8: Нэгж хичээлийн шалгалт | E8: MGL | F8: Монгол хэл | G8: EJ-2627-6A | H8: 6а | I8: Монгол хэл VI — I бүлгийн шалгалт | J8: 46302 | K8: 0.5
A9: ЖИШЭЭ | B9: QZ-6A-MATH-04 | C9: QUIZ | D9: Хичээлийн дараах сорил | E9: MATH | F9: Математик | G9: EJ-2627-6A | H9: 6а | I9: II.4 сэдвийн сорил | J9: 46286 | K9: 0.8 | L9: 5 минут. Нэг л удаа өгнө.
A10: ЖИШЭЭ | B10: EX-G7-MATH-T1 | C10: TERM | D10: Улирлын шалгалт | E10: MATH | F10: Математик | H10: (7-р анги бүхэлдээ) | I10: Математик VII — I улирлын шалгалт | J10: 46324 | K10: 0.6 | L10: Ангийн код хоосон = тухайн ангийн БҮХ анги өгнө
A12: Төрлийн код: QUIZ (хичээлийн дараах сорил), UNIT (нэгж хичээлийн), TERM (улирлын), YEAR (жилийн), DIAGNOSTIC (оношилгоо). Нийт оноо энд байхгүй — «22 Шалгалтын асуултууд» хуудсан дээрх оноонуудын нийлбэрээр тооцогдоно.

Sheet 22 Шалгалтын асуултууд
A1: Шалгалт ↔ асуулт (★ ШИНЭ)
A2: Шалгалт бүр ямар асуултаас, ямар дарааллаар бүрдэхийг заана. Нэг асуулт олон шалгалтад орж болно: Q-M6-0301 нь сорил, нэгж хичээлийн ба улирлын гурван шалгалтад бүгдэд нь байна. «Энэ шалгалт дээрх оноо» нь тухайн шалгалтад л хамаарна — нэг асуулт сорил дээр 1, улирлын шалгалт дээр 2 оноотой байж болно, асуултыг хуулж олшруулах шаардлагагүй. БААЗАД ХООСОН.
A3: ХООСОН — бүхэлдээ сургуулиас авах ёстой
A5: Төлөв | B5: Шалгалтын код | C5: Дараалал | D5: Асуултын код | E5: Асуулт | F5: Чадварын код | G5: Энэ шалгалт дээрх оноо | H5: Хүчинтэй оноо
A6: ЖИШЭЭ | B6: EX-6A-MATH-U1 | C6: 1 | D6: Q-M6-0101 | E6: 345 + 278 үйлдлийн үр дүнг ол. | F6: MATH-6-01 | H6: 1
A7: ЖИШЭЭ | B7: EX-6A-MATH-U1 | C7: 2 | D7: Q-M6-0301 | E7: 3.45 + 2.7 үйлдлийн үр дүнг ол. | F7: MATH-6-03 | H7: 1
A8: ЖИШЭЭ | B8: EX-6A-MATH-U1 | C8: 3 | D8: Q-M6-0302 | E8: 8.2 − 5.47 үйлдлийн үр дүнг ол. | F8: MATH-6-03 | H8: 1
A9: ЖИШЭЭ | B9: EX-6A-MATH-U1 | C9: 4 | D9: Q-M6-0303 | E9: 2.5 кг ба 1.75 кг жимсний нийлбэрийг ол. | F9: MATH-6-03 | H9: 2
A10: ЖИШЭЭ | B10: EX-6A-MATH-T1 | C10: 1 | D10: Q-M6-0301 | E10: 3.45 + 2.7 үйлдлийн үр дүнг ол. | F10: MATH-6-03 | G10: 2 | H10: 2
A11: ЖИШЭЭ | B11: EX-6A-MATH-T1 | C11: 2 | D11: Q-M6-0303 | E11: 2.5 кг ба 1.75 кг жимсний нийлбэрийг ол. | F11: MATH-6-03 | G11: 4 | H11: 4
A12: ЖИШЭЭ | B12: EX-6A-MATH-T1 | C12: 3 | D12: Q-M6-0401 | E12: 2.4 × 3 үйлдлийн үр дүнг ол. | F12: MATH-6-04 | G12: 2 | H12: 2
A13: ЖИШЭЭ | B13: QZ-6A-MATH-04 | C13: 1 | D13: Q-M6-0301 | E13: 3.45 + 2.7 үйлдлийн үр дүнг ол. | F13: MATH-6-03 | H13: 1
A14: ЖИШЭЭ | B14: QZ-6A-MATH-04 | C14: 2 | D14: Q-M6-0302 | E14: 8.2 − 5.47 үйлдлийн үр дүнг ол. | F14: MATH-6-03 | H14: 1
A15: ЖИШЭЭ | B15: EX-6A-MGL-U1 | C15: 1 | D15: Q-MGL6-0101 | E15: Өгүүлбэрээс жинхэнэ нэрийг ол. | F15: MGL-6-01 | H15: 2
A17: «Энэ шалгалт дээрх оноо» хоосон бол асуултын өөрийнх нь оноо хэрэглэгдэнэ — «Хүчинтэй оноо» багана тэрхүү эцсийн дүнг харуулна. Нийт оноог эндээс нэмж тооцно.

Sheet 23 Шалгалтын дүн
A1: Нэг сурагчийн нэг шалгалтын нийт дүн
A2: Сурагч шалгалт өгөх бүрд нэг мөр. Нийт оноо, хувь, тэнцсэн эсэх. Тэнцсэн эсэхийг «21 Шалгалт» хуудасны тэнцэх хувьтай харьцуулж шийднэ. БААЗАД ХООСОН.
A3: ХООСОН — бүхэлдээ сургуулиас авах ёстой
A5: Төлөв | B5: Сурагчийн код | C5: Овог нэр | D5: Анги | E5: Шалгалтын код | F5: Шалгалтын нэр | G5: Огноо | H5: Авсан оноо | I5: Нийт оноо | J5: Хувь | K5: Дүгнэлт | L5: Багшийн тэмдэглэл
A6: ЖИШЭЭ | B6: EJ-2627-S0108 | C6: Анхбаяр Дөлгөөнмөрөн | D6: 6а | E6: EX-6A-MATH-U1 | F6: Математик VI — I бүлгийн шалгалт | G6: 46300 | H6: 4 | I6: 5 | J6: =IF($I6=0,"",$H6/$I6) | K6: Тэнцсэн | L6: Бүхэл тоон дээр сайн
A7: ЖИШЭЭ | B7: EJ-2627-S0113 | C7: Аюушбаатар Мөнхжин | D7: 6а | E7: EX-6A-MATH-U1 | F7: Математик VI — I бүлгийн шалгалт | G7: 46300 | H7: 3 | I7: 5 | J7: =IF($I7=0,"",$H7/$I7) | K7: Тэнцсэн | L7: Хасах үйлдэл дээр алдав
A8: ЖИШЭЭ | B8: EJ-2627-S0129 | C8: Батбаяр Мишээл | D8: 6а | E8: EX-6A-MATH-U1 | F8: Математик VI — I бүлгийн шалгалт | G8: 46300 | H8: 2 | I8: 5 | J8: =IF($I8=0,"",$H8/$I8) | K8: Тэнцээгүй | L8: Бутархайн үйлдэл нөхөх ёстой
A9: ЖИШЭЭ | B9: EJ-2627-S0128 | C9: Батболд Амармэнд | D9: 6а | E9: EX-6A-MATH-U1 | F9: Математик VI — I бүлгийн шалгалт | G9: 46300 | H9: 5 | I9: 5 | J9: =IF($I9=0,"",$H9/$I9) | K9: Тэнцсэн | L9: Ахисан даалгавар өгч болно
A10: ЖИШЭЭ | B10: EJ-2627-S0127 | C10: Батсүх Хангал | D10: 6а | E10: EX-6A-MATH-U1 | F10: Математик VI — I бүлгийн шалгалт | G10: 46300 | H10: 3 | I10: 5 | J10: =IF($I10=0,"",$H10/$I10) | K10: Тэнцсэн
A12: Нийт оноо 5 нь «22 Шалгалтын асуултууд» дээрх EX-6A-MATH-U1-ийн дөрвөн асуултын нийлбэр (1+1+1+2). Тэнцэх хувь 60% тул 3 оноо шаардлагатай.

Sheet 24 Асуултын хариулт
A1: Асуулт тус бүрийн хариулт
A2: Сурагч асуулт бүрд юу хариулсан, хэдэн оноо авсан. Энэ хуудас л «чадвар эзэмшсэн эсэх»-ийг тооцоолох боломж олгоно: хариулт → асуулт → чадвар. Зөвхөн нийт оноо мэдэж байвал аль чадвар дутуу байгааг хэлж чадахгүй. БААЗАД ХООСОН.
A3: ХООСОН — бүхэлдээ сургуулиас авах ёстой
A5: Төлөв | B5: Сурагчийн код | C5: Овог нэр | D5: Шалгалтын код | E5: Асуултын код | F5: Асуулт | G5: Сурагчийн хариулт | H5: Авсан оноо | I5: Нийт оноо | J5: Хувь | K5: Зөв эсэх | L5: Үнэлсэн багш
A6: ЖИШЭЭ | B6: EJ-2627-S0129 | C6: Батбаяр Мишээл | D6: EX-6A-MATH-U1 | E6: Q-M6-0301 | F6: 3.45 + 2.7 = ? | G6: 5.15 | H6: 0 | I6: 1 | J6: =IF($I6=0,"",$H6/$I6) | K6: үгүй | L6: Б.Буянзаяа
A7: ЖИШЭЭ | B7: EJ-2627-S0129 | C7: Батбаяр Мишээл | D7: EX-6A-MATH-U1 | E7: Q-M6-0302 | F7: 8.2 − 5.47 = ? | G7: 2.83 | H7: 0 | I7: 1 | J7: =IF($I7=0,"",$H7/$I7) | K7: үгүй | L7: Б.Буянзаяа
A8: ЖИШЭЭ | B8: EJ-2627-S0129 | C8: Батбаяр Мишээл | D8: EX-6A-MATH-U1 | E8: Q-M6-0303 | F8: 2.5 кг ба 1.75 кг жимс | G8: 2.5 + 1.75 = 4.25 кг | H8: 2 | I8: 2 | J8: =IF($I8=0,"",$H8/$I8) | K8: ТИЙМ | L8: Б.Буянзаяа
A9: ЖИШЭЭ | B9: EJ-2627-S0108 | C9: Анхбаяр Дөлгөөнмөрөн | D9: EX-6A-MATH-U1 | E9: Q-M6-0301 | F9: 3.45 + 2.7 = ? | G9: 6.15 | H9: 1 | I9: 1 | J9: =IF($I9=0,"",$H9/$I9) | K9: ТИЙМ | L9: Б.Буянзаяа
A10: ЖИШЭЭ | B10: EJ-2627-S0108 | C10: Анхбаяр Дөлгөөнмөрөн | D10: EX-6A-MATH-U1 | E10: Q-M6-0302 | F10: 8.2 − 5.47 = ? | G10: 2.73 | H10: 1 | I10: 1 | J10: =IF($I10=0,"",$H10/$I10) | K10: ТИЙМ | L10: Б.Буянзаяа
A11: ЖИШЭЭ | B11: EJ-2627-S0113 | C11: Аюушбаатар Мөнхжин | D11: EX-6A-MATH-U1 | E11: Q-M6-0301 | F11: 3.45 + 2.7 = ? | G11: 6.15 | H11: 1 | I11: 1 | J11: =IF($I11=0,"",$H11/$I11) | K11: ТИЙМ | L11: Б.Буянзаяа
A12: ЖИШЭЭ | B12: EJ-2627-S0113 | C12: Аюушбаатар Мөнхжин | D12: EX-6A-MATH-U1 | E12: Q-M6-0302 | F12: 8.2 − 5.47 = ? | G12: 3.73 | H12: 0 | I12: 1 | J12: =IF($I12=0,"",$H12/$I12) | K12: үгүй | L12: Б.Буянзаяа
A14: Батбаяр Мишээл тооцооллын хоёр асуултад алдаж, бодлогын алхмаа зөв бичсэн — тэр нь «арга нь ойлгосон, тооцоолол сул» гэсэн өөр дүгнэлт. Нийт оноо үүнийг хэлж чадахгүй.

Sheet 25 Чадварын түвшин
A1: Сурагчийн чадварын түвшин (★ ЭЦСИЙН ҮР ДҮН)
A2: Сурагч бүр чадвар бүрийг ямар түвшинд эзэмшснийг харуулна. Энэ нь гараар бичигдэхгүй — «23 Асуултын хариулт» дээрээс автоматаар тооцогдоно. «Хувийн бэлтгэл»-д юу өгөхийг энэ хүснэгт шийднэ. БААЗАД ХООСОН.
A3: ХООСОН — бүхэлдээ сургуулиас авах ёстой
A5: Төлөв | B5: Сурагчийн код | C5: Овог нэр | D5: Анги | E5: Чадварын код | F5: Чадвар | G5: Түвшин | H5: Оноо (%) | I5: Оролдлого | J5: Сүүлд үнэлсэн | K5: Эх сурвалж
A6: ЖИШЭЭ | B6: EJ-2627-S0108 | C6: Анхбаяр Дөлгөөнмөрөн | D6: 6а | E6: MATH-6-03 | F6: Аравтын бутархайг нэмэх, хасах | G6: ЭЗЭМШСЭН | H6: 1 | I6: 1 | J6: 46300 | K6: Автомат
A7: ЖИШЭЭ | B7: EJ-2627-S0113 | C7: Аюушбаатар Мөнхжин | D7: 6а | E7: MATH-6-03 | F7: Аравтын бутархайг нэмэх, хасах | G7: АХИЦТАЙ | H7: 0.5 | I7: 1 | J7: 46300 | K7: Автомат
A8: ЖИШЭЭ | B8: EJ-2627-S0129 | C8: Батбаяр Мишээл | D8: 6а | E8: MATH-6-03 | F8: Аравтын бутархайг нэмэх, хасах | G8: ДУТУУ | H8: 0.5 | I8: 1 | J8: 46300 | K8: Автомат
